Workbook

Sheet 설계 안내
A1: 항목 | B1: 내용
A2: ※ 2차 개정 사항 | B2: 목표 영역에 「TD-7 경물·감각」을 추가하였습니다. 시범 코딩에서 경물 묘사와 감각·정서 표현이 갈 자리가 없어 TD-6 기타에 몰리는 문제가 확인되었기 때문입니다. 기행문에서 견문을 서술하는 대목은 대체로 TD-7에 듭니다. TD-6은 나머지 여섯에 모두 들지 않을 때만 쓰고, 그때는 비고란에 무엇인지 적어 주십시오.
A3: 이 파일의 용도 | B3: 「화식열전」과 열하일기 7편 전체를 새 설계로 재코딩하기 위한 판정지입니다. 두 판정자가 각자 사본에 독립적으로 입력한 뒤 대조합니다.
A4: 작업량 | B4: 판정 대상 절은 8편 합계 1,880절입니다. 절당 30초로 잡으면 1인 약 16시간입니다. 먼저 한 편을 끝까지 해보고 실제 속도를 확인한 뒤 전체 일정을 잡으시기를 권합니다.
A5: 작업 순서 권고 | B5: 「화식열전」과 「도강록」을 먼저 하십시오. 이 두 편(718절)은 건별 자료가 아예 없어 심사의견 2·5·6·7번의 공통 원인이 되고 있습니다. 나머지 6편은 기존 판정 자료가 남아 있으므로 후순위로 두어도 됩니다.
A6: 분석 단위 — 절(節) | B6: 두 저본이 각자 표시한 경계를 그대로 씁니다. 「화식열전」은 표점(，。：；)으로, 열하일기는 저본의 띄어쓰기로 나눕니다. 연구자가 임의로 정한 분절이 아닙니다.
A7: 두 저본의 절 길이가 사실상 같습니다 | B7: 「화식열전」 1,155절 평균 4.14자(중위 4.0), 열하일기 16,278절 평균 4.98자(중위 4.0)입니다. 표점의 쉼표와 저본의 띄어쓰기가 같은 층위의 경계를 표시한다는 뜻이며, 심사의견 4번에 대한 실질적 해결책이 됩니다.
A8: 판정 대상 선정 | B8: 트리거 41개를 포함한 절과 그 앞뒤 각 1절이 대상입니다. 두 문헌에 같은 규칙을 적용합니다.
A9: 음성 사례를 반드시 남기십시오 | B9: 기존 검토표는 은유로 판정된 건만 기록되어 은유 여부의 Kappa를 산출할 수 없었습니다. 이번에는 대상 절 전체를 Y/N으로 판정하므로 음성 사례가 남습니다. 은유가 아닌 절도 빠짐없이 N으로 표시해 주십시오. 빈칸으로 두면 미판정과 구별되지 않습니다.
A10: 목표 영역을 함께 코딩합니다 | B10: 모든 은유 항목에 목표 영역 코드를 붙입니다. 그러면 원천 × 목표 교차표가 산출되어, 대응쌍을 골라 제시할 필요가 없어집니다. 심사의견 5번이 여기서 해소됩니다.
A11: 판정 방법 | B11: ① 절의 문맥적 의미를 확인합니다. ② 해당 어휘의 기본 의미(더 구체적이고 신체적 경험에 가까우며 역사적으로 앞선 의미)를 떠올립니다. ③ 두 의미가 다르고 전자를 후자와의 비교로 이해할 수 있으면 Y로 판정합니다. ④ Y라면 원천 영역과 목표 영역을 각각 고르고 해당 어휘를 적습니다.
A12: 과장·역설의 처리 | B12: 과장이나 역설은 두 영역 사이의 사상이 아니므로 원천 영역이 아닙니다. 그것만으로 이루어진 표현은 원천 영역에 「(수사 기제)」를 선택하십시오. 원천 영역과 함께 나타나면 원천 영역을 고르고 비고란에 적으십시오.
... A15: 심세편에 관한 유의 | B15: 「심세편」은 판정 대상이 21절에 그칩니다. 재코딩 후에도 정량표에 넣기 어려울 가능성이 높으나, 판정해 두면 제외 근거를 수치로 제시할 수 있습니다.

Sheet 진행 현황
A1: 텍스트 | B1: 판정 대상 절 | C1: 판정 완료 | D1: 미판정 | E1: 은유(Y) | F1: 비은유(N)
A2: 화식열전 | B2: 394 | C2: =COUNTIF(화식열전!$H$2:$H$395,"Y")+COUNTIF(화식열전!$H$2:$H$395,"N") | D2: =B2-C2 | E2: =COUNTIF(화식열전!$H$2:$H$395,"Y") | F2: =COUNTIF(화식열전!$H$2:$H$395,"N")
A3: 도강록 | B3: 324 | C3: =COUNTIF(도강록!$H$2:$H$325,"Y")+COUNTIF(도강록!$H$2:$H$325,"N") | D3: =B3-C3 | E3: =COUNTIF(도강록!$H$2:$H$325,"Y") | F3: =COUNTIF(도강록!$H$2:$H$325,"N")
A4: 성경잡지 | B4: 295 | C4: =COUNTIF(성경잡지!$H$2:$H$296,"Y")+COUNTIF(성경잡지!$H$2:$H$296,"N") | D4: =B4-C4 | E4: =COUNTIF(성경잡지!$H$2:$H$296,"Y") | F4: =COUNTIF(성경잡지!$H$2:$H$296,"N")
A5: 일신수필 | B5: 273 | C5: =COUNTIF(일신수필!$H$2:$H$274,"Y")+COUNTIF(일신수필!$H$2:$H$274,"N") | D5: =B5-C5 | E5: =COUNTIF(일신수필!$H$2:$H$274,"Y") | F5: =COUNTIF(일신수필!$H$2:$H$274,"N")
A6: 관내정사 | B6: 254 | C6: =COUNTIF(관내정사!$H$2:$H$255,"Y")+COUNTIF(관내정사!$H$2:$H$255,"N") | D6: =B6-C6 | E6: =COUNTIF(관내정사!$H$2:$H$255,"Y") | F6: =COUNTIF(관내정사!$H$2:$H$255,"N")
A7: 옥갑야화 | B7: 254 | C7: =COUNTIF(옥갑야화!$H$2:$H$255,"Y")+COUNTIF(옥갑야화!$H$2:$H$255,"N") | D7: =B7-C7 | E7: =COUNTIF(옥갑야화!$H$2:$H$255,"Y") | F7: =COUNTIF(옥갑야화!$H$2:$H$255,"N")
A8: 행재잡록 | B8: 65 | C8: =COUNTIF(행재잡록!$H$2:$H$66,"Y")+COUNTIF(행재잡록!$H$2:$H$66,"N") | D8: =B8-C8 | E8: =COUNTIF(행재잡록!$H$2:$H$66,"Y") | F8: =COUNTIF(행재잡록!$H$2:$H$66,"N")
A9: 심세편 | B9: 21 | C9: =COUNTIF(심세편!$H$2:$H$22,"Y")+COUNTIF(심세편!$H$2:$H$22,"N") | D9: =B9-C9 | E9: =COUNTIF(심세편!$H$2:$H$22,"Y") | F9: =COUNTIF(심세편!$H$2:$H$22,"N")
A10: 합계 | B10: =SUM(B2:B9) | C10: =SUM(C2:C9) | D10: =SUM(D2:D9) | E10: =SUM(E2:E9) | F10: =SUM(F2:F9)

Sheet 화식열전
A1: 연번 | B1: 문단 | C1: 절번호 | D1: 앞 절 | E1: 판정 대상 절 | F1: 뒤 절 | G1: 트리거 | H1: 은유 여부 | I1: 원천 영역 | J1: 목표 영역 | K1: 원천 어휘 | L1: 목표 개념 | M1: 판정 근거 | N1: 확신도 | O1: 비고
A2: 1 | B2: 2 | C2: 13 | D2: 終不能化 | E2: 故善者因之 | F2: 其次利道之
A3: 2 | B3: 2 | C3: 14 | D3: 故善者因之 | E3: 其次利道之 | F3: 其次教誨之 | G3: ●
A4: 3 | B4: 2 | C4: 15 | D4: 其次利道之 | E4: 其次教誨之 | F4: 其次整齊之
A5: 4 | B5: 3 | C5: 38 | D5: 虞而出之 | E5: 工而成之 | F5: 商而通之
A6: 5 | B6: 3 | C6: 39 | D6: 工而成之 | E6: 商而通之 | F6: 此寧有政教發徵期會哉 | G6: ●
A7: 6 | B7: 3 | C7: 40 | D7: 商而通之 | E7: 此寧有政教發徵期會哉 | F7: 人各任其能
A8: 7 | B8: 4 | C8: 3 | D8: 農不出則乏其食 | E8: 工不出則乏其事 | F8: 商不出則三寶絕
A9: 8 | B9: 4 | C9: 4 | D9: 工不出則乏其事 | E9: 商不出則三寶絕 | F9: 虞不出則財匱少 | G9: ●
A10: 9 | B10: 4 | C10: 5 | D10: 商不出則三寶絕 | E10: 虞不出則財匱少 | F10: 財匱 | G10: ●
A11: 10 | B11: 4 | C11: 6 | D11: 虞不出則財匱少 | E11: 財匱 | F11: 少而山澤不辟矣 | G11: ●
A12: 11 | B12: 4 | C12: 7 | D12: 財匱 | E12: 少而山澤不辟矣 | F12: 此四者
A13: 12 | B13: 4 | C13: 11 | D13: 原大則饒 | E13: 原小則鮮 | F13: 上則富國
A14: 13 | B14: 4 | C14: 12 | D14: 原小則鮮 | E14: 上則富國 | F14: 下則富家 | G14: ●
A15: 14 | B15: 4 | C15: 13 | D15: 上則富國 | E15: 下則富家 | F15: 貧富 | G15: ●
A16: 15 | B16: 4 | C16: 14 | D16: 下則富家 | E16: 貧富 | F16: 之道 | G16: ●
A17: 16 | B17: 4 | C17: 15 | D17: 貧富 | E17: 之道 | F17: 莫之奪予
A18: 17 | B18: 4 | C18: 39 | D18: 歸 | E18: 位在陪臣 | F18: 富於列國之君
A19: 18 | B19: 4 | C19: 40 | D19: 位在陪臣 | E19: 富於列國之君 | F19: 是以齊富彊至於威 | G19: ●
A20: 19 | B20: 4 | C20: 41 | D20: 富於列國之君 | E20: 是以齊富彊至於威 | F20: 宣也 | G20: ●
A21: 20 | B21: 4 | C21: 42 | D21: 是以齊富彊至於威 | E21: 宣也
A22: 21 | B22: 5 | C22: 4 | D22: 衣食足而知榮辱 | E22: 禮生於有而廢於無 | F22: 故君子富
A23: 22 | B23: 5 | C23: 5 | D23: 禮生於有而廢於無 | E23: 故君子富 | F23: 好行其德 | G23: ●
A24: 23 | B24: 5 | C24: 6 | D24: 故君子富 | E24: 好行其德 | F24: 小人
A25: 24 | B25: 5 | C25: 7 | D25: 好行其德 | E25: 小人 | F25: 富
A26: 25 | B26: 5 | C26: 8 | D26: 小人 | E26: 富 | F26: 以適其力 | G26: ●
A27: 26 | B27: 5 | C27: 9 | D27: 富 | E27: 以適其力 | F27: 淵深而魚生之
A28: 27 | B28: 5 | C28: 11 | D28: 淵深而魚生之 | E28: 山深而獸往之 | F28: 人富而仁義附焉
A29: 28 | B29: 5 | C29: 12 | D29: 山深而獸往之 | E29: 人富而仁義附焉 | F29: 富者得埶益彰 | G29: ●
A30: 29 | B30: 5 | C30: 13 | D30: 人富而仁義附焉 | E30: 富者得埶益彰 | F30: 失埶則客無所 | G30: ●
A31: 30 | B31: 5 | C31: 14 | D31: 富者得埶益彰 | E31: 失埶則客無所 | F31: 之
A32: 31 | B32: 5 | C32: 18 | D32: 夷狄益甚 | E32: 諺曰 | F32: 千金之子
A33: 32 | B33: 5 | C33: 19 | D33: 諺曰 | E33: 千金之子 | F33: 不死於市 | G33: ●
A34: 33 | B34: 5 | C34: 20 | D34: 千金之子 | E34: 不死於市 | F34: 此非空言也
A35: 34 | B35: 5 | C35: 23 | D35: 故曰 | E35: 天下熙熙 | F35: 皆為利來
A36: 35 | B36: 5 | C36: 24 | D36: 天下熙熙 | E36: 皆為利來 | F36: 天下壤壤 | G36: ●
A37: 36 | B37: 5 | C37: 25 | D37: 皆為利來 | E37: 天下壤壤 | F37: 皆為利往
A38: 37 | B38: 5 | C38: 26 | D38: 天下壤壤 | E38: 皆為利往 | F38: 夫千乘之王 | G38: ●
A39: 38 | B39: 5 | C39: 27 | D39: 皆為利往 | E39: 夫千乘之王 | F39: 萬家之侯
A40: 39 | B40: 5 | C40: 29 | D40: 萬家之侯 | E40: 百室之君 | F40: 尚猶患貧
...

Sheet 도강록
A1: 연번 | B1: 문단 | C1: 절번호 | D1: 앞 절 | E1: 판정 대상 절 | F1: 뒤 절 | G1: 트리거 | H1: 은유 여부 | I1: 원천 영역 | J1: 목표 영역 | K1: 원천 어휘 | L1: 목표 개념 | M1: 판정 근거 | N1: 확신도 | O1: 비고
A2: 1 | B2: 7 | C2: 10 | D2: 徐往舘所 | E2: 諸裨已著軍服戰笠矣 | F2: 頂起銀花雲月
A3: 2 | B3: 7 | C3: 11 | D3: 諸裨已著軍服戰笠矣 | E3: 頂起銀花雲月 | F3: 懸孔雀羽 | G3: ●
A4: 3 | B4: 7 | C4: 12 | D4: 頂起銀花雲月 | E4: 懸孔雀羽 | F4: 腰繫藍方紗紬纏帶
A5: 4 | B5: 8 | C5: 38 | D5: 者 | E5: 自檢其囊中得廿六文 | F5: 而東錢有禁
A6: 5 | B6: 8 | C6: 39 | D6: 自檢其囊中得廿六文 | E6: 而東錢有禁 | F6: 不可出境 | G6: ●
A7: 6 | B7: 8 | C7: 40 | D7: 而東錢有禁 | E7: 不可出境 | F7: 棄之道則可惜
A8: 7 | B8: 8 | C8: 56 | D8: 滿酌一盞 | E8: 酹第一柱 | F8: 自祈利涉
A9: 8 | B9: 8 | C9: 57 | D9: 酹第一柱 | E9: 自祈利涉 | F9: 又斟一杯 | G9: ●
A10: 9 | B10: 8 | C10: 58 | D10: 自祈利涉 | E10: 又斟一杯 | F10: 酹第二柱
A11: 10 | B11: 9 | C11: 9 | D11: 紅粉樓中別莫愁 | E11: 秋風數騎出邊頭 | F11: 畵船簫鼓無消息
A12: 11 | B12: 9 | C12: 10 | D12: 秋風數騎出邊頭 | E12: 畵船簫鼓無消息 | F12: 斷膓淸南第一州 | G12: ●
A13: 12 | B13: 9 | C13: 11 | D13: 畵船簫鼓無消息 | E13: 斷膓淸南第一州 | F13: 此柳惠風入瀋陽時作也
A14: 13 | B14: 10 | C14: 22 | D14: 舊件新浣 | E14: 鬅騰郭索 | F14: 可謂太崇儉矣
A15: 14 | B15: 10 | C15: 23 | D15: 鬅騰郭索 | E15: 可謂太崇儉矣 | F15: 稍俟副使之出城 | G15: ●
A16: 15 | B16: 10 | C16: 24 | D16: 可謂太崇儉矣 | E16: 稍俟副使之出城 | F16: 乃按轡徐行
A17: 16 | B17: 10 | C17: 37 | D17: 搜其禁物 | E17: 大者如黃金眞珠人參貂皮 | F17: 及包外濫銀
A18: 17 | B18: 10 | C18: 38 | D18: 大者如黃金眞珠人參貂皮 | E18: 及包外濫銀 | F18: 小者新舊名目 | G18: ●
A19: 18 | B19: 10 | C19: 39 | D19: 及包外濫銀 | E19: 小者新舊名目 | F19: 不下數十種
A20: 19 | B20: 10 | C20: 54 | D20: 而其實 | E20: 文具而已 | F20: 灣賈之先期潛越
A21: 20 | B21: 10 | C21: 55 | D21: 文具而已 | E21: 灣賈之先期潛越 | F21: 有誰禁之 | G21: ●
A22: 21 | B22: 10 | C22: 56 | D22: 灣賈之先期潛越 | E22: 有誰禁之 | F22: 禁物之現捉於初旗者
A23: 22 | B23: 10 | C23: 66 | D23: 今行原包猶未及半 | E23: 多空包者 | F23: 其濫銀奚論
A24: 23 | B24: 10 | C24: 67 | D24: 多空包者 | E24: 其濫銀奚論 | G24: ●
A25: 24 | B25: 11 | C25: 1 | E25: 茶啖草草 | F25: 乍進旋退
A26: 25 | B26: 11 | C26: 64 | D26: 惟 | E26: 知道者能之 | F26: 鄭之子產
A27: 26 | B27: 11 | C27: 65 | D27: 知道者能之 | E27: 鄭之子產 | G27: ●
A28: 27 | B28: 12 | C28: 1 | E28: 船已泊岸 | F28: 蘆荻如織
A29: 28 | B29: 12 | C29: 36 | D29: 有一人起立應聲曰 | E29: 爾們的不時節 | F29: 緣何朝貢入大國
A30: 29 | B30: 12 | C30: 37 | D30: 爾們的不時節 | E30: 緣何朝貢入大國 | F30: 暑天裏長途 | G30: ●
A31: 30 | B31: 12 | C31: 38 | D31: 緣何朝貢入大國 | E31: 暑天裏長途 | F31: 辛苦時大
A32: 31 | B32: 12 | C32: 133 | D32: 余騰身載其背 | E32: 其人笑嘻嘻入船 | F32: 出氣長息曰
A33: 32 | B33: 12 | C33: 134 | D33: 其人笑嘻嘻入船 | E33: 出氣長息曰 | F33: 黑旋風媽媽這樣沉挑時 | G33: ●
A34: 33 | B34: 12 | C34: 135 | D34: 出氣長息曰 | E34: 黑旋風媽媽這樣沉挑時 | F34: 巴不得上了沂
A35: 34 | B35: 13 | C35: 46 | D35: 或五人同帳 | E35: 譯卒及刷馬驅人 | F35: 伍伍什什
A36: 35 | B36: 13 | C36: 47 | D36: 譯卒及刷馬驅人 | E36: 伍伍什什 | F36: 靠溪搆木 | G36: ●
A37: 36 | B37: 13 | C37: 48 | D37: 伍伍什什 | E37: 靠溪搆木 | F37: 炊烟相連
A38: 37 | B38: 13 | C38: 52 | D38: 儼 | E38: 成村閭 | F38: 灣商一隊
A39: 38 | B39: 13 | C39: 53 | D39: 成村閭 | E39: 灣商一隊 | F39: 自爲一屯 | G39: ●
A40: 39 | B40: 13 | C40: 54 | D40: 灣商一隊 | E40: 自爲一屯 | F40: 臨溪洗數十鷄
...

Sheet 성경잡지
A1: 연번 | B1: 문단 | C1: 절번호 | D1: 앞 절 | E1: 판정 대상 절 | F1: 뒤 절 | G1: 트리거 | H1: 은유 여부 | I1: 원천 영역 | J1: 목표 영역 | K1: 원천 어휘 | L1: 목표 개념 | M1: 판정 근거 | N1: 확신도 | O1: 비고
A2: 1 | B2: 8 | C2: 59 | D2: 少焉主人之小孫 | E2: 手提吶叭 | F2: 氣息喘喘
A3: 2 | B3: 8 | C3: 60 | D3: 手提吶叭 | E3: 氣息喘喘 | F3: 走入堂裏 | G3: ●
A4: 3 | B4: 8 | C4: 61 | D4: 氣息喘喘 | E4: 走入堂裏 | F4: 抱老公項
A5: 4 | B5: 8 | C5: 62 | D5: 走入堂裏 | E5: 抱老公項 | F5: 要買吶叭
A6: 5 | B6: 8 | C6: 63 | D6: 抱老公項 | E6: 要買吶叭 | F6: 老公慈意滿面曰 | G6: ●
A7: 6 | B7: 8 | C7: 64 | D7: 要買吶叭 | E7: 老公慈意滿面曰 | F7: 這箇不中用
A8: 7 | B8: 8 | C8: 82 | D8: 余亦責軍牢索去好矣 | E8: 何必若是無聊人 | F8: 余問這狗子那地所產
A9: 8 | B9: 8 | C9: 83 | D9: 何必若是無聊人 | E9: 余問這狗子那地所產 | F9: 主人 | G9: ●
A10: 9 | B10: 8 | C10: 84 | D10: 余問這狗子那地所產 | E10: 主人 | F10: 答曰
A11: 10 | B11: 8 | C11: 85 | D11: 主人 | E11: 答曰 | F11: 雲南所產
A12: 11 | B12: 8 | C12: 86 | D12: 答曰 | E12: 雲南所產 | F12: 蜀中亦有這樣的小狗 | G12: ●
A13: 12 | B13: 8 | C13: 87 | D13: 雲南所產 | E13: 蜀中亦有這樣的小狗 | F13: 此名玉兎兒
A14: 13 | B14: 8 | C14: 89 | D14: 此名玉兎兒 | E14: 那箇叫做雪獅子 | F14: 幷是雲南產
A15: 14 | B15: 8 | C15: 90 | D15: 那箇叫做雪獅子 | E15: 幷是雲南產 | F15: 主人叫玉兎兒 | G15: ●
A16: 15 | B16: 8 | C16: 91 | D16: 幷是雲南產 | E16: 主人叫玉兎兒 | F16: 叩頭
A17: 16 | B17: 8 | C17: 100 | D17: 客官旣然愛玩此 | E17: 微物時 | F17: 情願拜送準貢回還時
A18: 17 | B18: 8 | C18: 101 | D18: 微物時 | E18: 情願拜送準貢回還時 | F18: 客官不妨携去 | G18: ●
A19: 18 | B19: 8 | C19: 102 | D19: 情願拜送準貢回還時 | E19: 客官不妨携去 | F19: 余答曰
A20: 19 | B20: 8 | C20: 113 | D20: 遂給張福與昌大共食 | E20: 自入舖子裏 | F20: 買喫一椀麵
A21: 20 | B21: 8 | C21: 114 | D21: 自入舖子裏 | E21: 買喫一椀麵 | F21: 一 | G21: ●
A22: 21 | B22: 8 | C22: 115 | D22: 買喫一椀麵 | E22: 一 | F22: 觶燒酒
A23: 22 | B23: 9 | C23: 15 | D23: 車馬雲屯 | E23: 促鞭行下馬少憩 | F23: 客商數百人
A24: 23 | B24: 9 | C24: 16 | D24: 促鞭行下馬少憩 | E24: 客商數百人 | F24: 卸擔納凉 | G24: ●
A25: 24 | B25: 9 | C25: 17 | D25: 客商數百人 | E25: 卸擔納凉 | F25: 或踞柳根
A26: 25 | B26: 9 | C26: 36 | D26: 車三十餘乘 | E26: 皆滿載石煤 | F26: 賣酒賣茶
A27: 26 | B27: 9 | C27: 37 | D27: 皆滿載石煤 | E27: 賣酒賣茶 | F27: 賣餠果 | G27: ●
A28: 27 | B28: 9 | C28: 38 | D28: 賣酒賣茶 | E28: 賣餠果 | F28: 諸般飮食者 | G28: ●
A29: 28 | B29: 9 | C29: 39 | D29: 賣餠果 | E29: 諸般飮食者 | F29: 皆聚柳陰下
A30: 29 | B30: 10 | C30: 1 | E30: 渾河 | F30: 一名阿利江
A31: 30 | B31: 10 | C31: 2 | D31: 渾河 | E31: 一名阿利江 | F31: 一名小遼水 | G31: ●
A32: 31 | B32: 10 | C32: 3 | D32: 一名阿利江 | E32: 一名小遼水 | F32: 源出長白山
A33: 32 | B33: 11 | C33: 15 | D33: 郭內民物之繁華 | E33: 市肆之侈盛 | F33: 十倍遼陽
A34: 33 | B34: 11 | C34: 16 | D34: 市肆之侈盛 | E34: 十倍遼陽 | F34: 矣 | G34: ●
A35: 34 | B35: 11 | C35: 17 | D35: 十倍遼陽 | E35: 矣 | F35: 入關廟少憩
A36: 35 | B36: 11 | C36: 32 | D36: 身披一領野繭紗道袍 | E36: 項戴藤笠 | F36: 足穿貢緞黑靴
A37: 36 | B37: 11 | C37: 33 | D37: 項戴藤笠 | E37: 足穿貢緞黑靴 | F37: 脫笠自撫其髻曰 | G37: ●
A38: 37 | B38: 11 | C38: 34 | D38: 足穿貢緞黑靴 | E38: 脫笠自撫其髻曰 | F38: 與相公一樣
A39: 38 | B39: 12 | C39: 17 | D39: 彩閣雕牕 | E39: 金扁碧榜 | F39: 貨寶
A40: 39 | B40: 12 | C40: 18 | D40: 金扁碧榜 | E40: 貨寶 | F40: 財賄 | G40: ●
...

Sheet 일신수필
A1: 연번 | B1: 문단 | C1: 절번호 | D1: 앞 절 | E1: 판정 대상 절 | F1: 뒤 절 | G1: 트리거 | H1: 은유 여부 | I1: 원천 영역 | J1: 목표 영역 | K1: 원천 어휘 | L1: 목표 개념 | M1: 판정 근거 | N1: 확신도 | O1: 비고
A2: 1 | B2: 3 | C2: 20 | D2: 吾今疾書至此 | E2: 而一墨之頃 | F2: 不過瞬息
A3: 2 | B3: 3 | C3: 21 | D3: 而一墨之頃 | E3: 不過瞬息 | F3: 一瞬一息之頃 | G3: ●
A4: 3 | B4: 3 | C4: 22 | D4: 不過瞬息 | E4: 一瞬一息之頃 | F4: 奄成小古小今 | G4: ●
A5: 4 | B5: 3 | C5: 23 | D5: 一瞬一息之頃 | E5: 奄成小古小今 | F5: 則一古一今
A6: 5 | B6: 3 | C6: 25 | D6: 則一古一今 | E6: 亦可謂大瞬 | F6: 大息矣
A7: 6 | B7: 3 | C7: 26 | D7: 亦可謂大瞬 | E7: 大息矣 | F7: 乃欲立名立事於其間 | G7: ●
A8: 7 | B8: 3 | C8: 27 | D8: 大息矣 | E8: 乃欲立名立事於其間 | F8: 豈不哀哉
A9: 8 | B9: 3 | C9: 35 | D9: 霧漫漫 | E9: 上承月光 | F9: 如水銀海
A10: 9 | B10: 3 | C10: 36 | D10: 上承月光 | E10: 如水銀海 | F10: 海底殷殷有聲如鼾鼻 | G10: ●
A11: 10 | B11: 3 | C11: 37 | D11: 如水銀海 | E11: 海底殷殷有聲如鼾鼻 | F11: 寺僧相語曰
A12: 11 | B12: 4 | C12: 60 | D12: 士庶人也薙髮 | E12: 雖功德侔殷周 | F12: 富强邁秦漢
A13: 12 | B13: 4 | C13: 61 | D13: 雖功德侔殷周 | E13: 富强邁秦漢 | F13: 自生民以來 | G13: ●
A14: 13 | B14: 4 | C14: 62 | D14: 富强邁秦漢 | E14: 自生民以來 | F14: 未有薙髮之天子也
A15: 14 | B15: 4 | C15: 136 | D15: 固自 | E15: 在也 | F15: 正德利用厚生之具
A16: 15 | B16: 4 | C16: 137 | D16: 在也 | E16: 正德利用厚生之具 | F16: 固自如也 | G16: ●
A17: 16 | B17: 4 | C17: 138 | D17: 正德利用厚生之具 | E17: 固自如也 | F17: 崔盧王謝之氏族固不廢也
A18: 17 | B18: 4 | C18: 145 | D18: 固不變也 | E18: 彼胡虜者 | F18: 誠知中國之可利
A19: 18 | B19: 4 | C19: 146 | D19: 彼胡虜者 | E19: 誠知中國之可利 | F19: 而足以久享 | G19: ●
A20: 19 | B20: 4 | C20: 147 | D20: 誠知中國之可利 | E20: 而足以久享 | F20: 則至於奪而據
A21: 20 | B21: 4 | C21: 151 | D21: 若固有之 | E21: 爲天下者 | F21: 苟利於民而厚於國
A22: 21 | B22: 4 | C22: 152 | D22: 爲天下者 | E22: 苟利於民而厚於國 | F22: 雖其法之或出於夷狄 | G22: ●
A23: 22 | B23: 4 | C23: 153 | D23: 苟利於民而厚於國 | E23: 雖其法之或出於夷狄 | F23: 固將取而則之
A24: 23 | B24: 4 | C24: 166 | D24: 自耕蠶陶冶 | E24: 以至通 | F24: 工惠商
A25: 24 | B25: 4 | C25: 167 | D25: 以至通 | E25: 工惠商 | F25: 莫不學焉 | G25: ●
A26: 25 | B26: 4 | C26: 168 | D26: 工惠商 | E26: 莫不學焉 | F26: 人十己百
A27: 26 | B27: 4 | C27: 169 | D27: 莫不學焉 | E27: 人十己百 | F27: 先利吾民
A28: 27 | B28: 4 | C28: 170 | D28: 人十己百 | E28: 先利吾民 | F28: 使吾民制梃 | G28: ●
A29: 28 | B29: 4 | C29: 171 | D29: 先利吾民 | E29: 使吾民制梃 | F29: 而足以撻彼之堅甲利兵
A30: 29 | B30: 4 | C30: 172 | D30: 使吾民制梃 | E30: 而足以撻彼之堅甲利兵 | F30: 然後謂中國無可觀可 | G30: ●
A31: 30 | B31: 4 | C31: 173 | D31: 而足以撻彼之堅甲利兵 | E31: 然後謂中國無可觀可 | F31: 也
A32: 31 | B32: 4 | C32: 184 | D32: 爲波濤之紋 | E32: 四合而成連環之形 | F32: 四背而成古魯錢
A33: 32 | B33: 4 | C33: 185 | D33: 四合而成連環之形 | E33: 四背而成古魯錢 | F33: 嵌空玲瓏 | G33: ●
A34: 33 | B34: 4 | C34: 186 | D34: 四背而成古魯錢 | E34: 嵌空玲瓏 | F34: 外內交映
A35: 34 | B35: 4 | C35: 191 | D35: 之文章斯在矣 | E35: 民家門庭 | F35: 貧不能鋪甎
A36: 35 | B36: 4 | C36: 192 | D36: 民家門庭 | E36: 貧不能鋪甎 | F36: 則聚諸色琉璃碎瓦及水邊小礫之磨圓者 | G36: ●
A37: 36 | B37: 4 | C37: 193 | D37: 貧不能鋪甎 | E37: 則聚諸色琉璃碎瓦及水邊小礫之磨圓者 | F37: 錯成花樹鳥獸之形
A38: 37 | B38: 6 | C38: 41 | D38: 舜封十有二山 | E38: 以醫巫閭爲幽州之鎭 | F38: 夏商周秦皆因之
A39: 38 | B39: 6 | C39: 42 | D39: 以醫巫閭爲幽州之鎭 | E39: 夏商周秦皆因之 | F39: 禮視嶽瀆 | G39: ●
A40: 39 | B40: 6 | C40: 43 | D40: 夏商周秦皆因之 | E40: 禮視嶽瀆 | F40: 雖未知廟刱何代
...

Sheet 관내정사
A1: 연번 | B1: 문단 | C1: 절번호 | D1: 앞 절 | E1: 판정 대상 절 | F1: 뒤 절 | G1: 트리거 | H1: 은유 여부 | I1: 원천 영역 | J1: 목표 영역 | K1: 원천 어휘 | L1: 목표 개념 | M1: 판정 근거 | N1: 확신도 | O1: 비고
A2: 1 | B2: 4 | C2: 114 | D2: 渭謂高麗紙 | E2: 不宜畵 | F2: 惟錢厚者稍佳
A3: 2 | B3: 4 | C3: 115 | D3: 不宜畵 | E3: 惟錢厚者稍佳 | F3: 其不見可 | G3: ●
A4: 3 | B4: 4 | C4: 116 | D4: 惟錢厚者稍佳 | E4: 其不見可 | F4: 如此
A5: 4 | B5: 4 | C5: 208 | D5: 余進至池邊 | E5: 暫倚欄干而立 | F5: 堂中寂然屛息
A6: 5 | B6: 4 | C6: 209 | D6: 暫倚欄干而立 | E6: 堂中寂然屛息 | F6: 隱暎從簾隙偸看 | G6: ●
A7: 6 | B7: 4 | C7: 210 | D7: 堂中寂然屛息 | E7: 隱暎從簾隙偸看 | F7: 余徘徊
A8: 7 | B8: 4 | C8: 314 | D8: 至昌黎諸濱海之縣 | E8: 山氣尤佳 | F8: 禹貢碣石
A9: 8 | B9: 4 | C9: 315 | D9: 山氣尤佳 | E9: 禹貢碣石 | F9: 近在縣西二十里 | G9: ●
A10: 9 | B10: 4 | C10: 316 | D10: 禹貢碣石 | E10: 近在縣西二十里 | F10: 曹操詩
A11: 10 | B11: 4 | C11: 353 | D11: 抱城逶迤 | E11: 地形甚似平壤 | F11: 而昭曠倍之
A12: 11 | B12: 4 | C12: 354 | D12: 地形甚似平壤 | E12: 而昭曠倍之 | F12: 而但無大同淸江耳 | G12: ●
A13: 12 | B13: 4 | C13: 355 | D13: 而昭曠倍之 | E13: 而但無大同淸江耳 | F13: 世傳金學士黃元登浮
A14: 13 | B14: 4 | C14: 389 | D14: 輔之地 | E14: 廬舍市舖 | F14: 繁富倍他
A15: 14 | B15: 4 | C15: 390 | D15: 廬舍市舖 | E15: 繁富倍他 | F15: 進士牌額 | G15: ●
A16: 15 | B16: 4 | C16: 391 | D16: 繁富倍他 | E16: 進士牌額 | F16: 比撫寧尤盛
A17: 16 | B17: 4 | C17: 397 | D17: 偶入一宅 | E17: 方張燈 | F17: 刻高麗進貢圖
A18: 17 | B18: 4 | C18: 398 | D18: 方張燈 | E18: 刻高麗進貢圖 | F18: 沿路店壁 | G18: ●
A19: 18 | B19: 4 | C19: 399 | D19: 刻高麗進貢圖 | E19: 沿路店壁 | F19: 多貼此畵
A20: 19 | B20: 4 | C20: 435 | D20: 墨鱗成堆 | E20: 破敗荒陋 | F20: 不直一錢
A21: 20 | B21: 4 | C21: 436 | D21: 破敗荒陋 | E21: 不直一錢 | F21: 第觀胡生擧措 | G21: ●
A22: 21 | B22: 4 | C22: 437 | D22: 不直一錢 | E22: 第觀胡生擧措 | F22: 眞若絶世奇寶
A23: 22 | B23: 4 | C23: 457 | D23: 曰 | E23: 晡刻貴國金相公 | F23: 來弊舖賣此
A24: 23 | B24: 4 | C24: 458 | D24: 晡刻貴國金相公 | E24: 來弊舖賣此 | F24: 金相公老實人 | G24: ●
A25: 24 | B25: 4 | C25: 459 | D25: 來弊舖賣此 | E25: 金相公老實人 | F25: 與俺情同嫡親兄弟
A26: 25 | B26: 4 | C26: 460 | D26: 金相公老實人 | E26: 與俺情同嫡親兄弟 | F26: 俺以三兩五分紋銀收買
A27: 26 | B27: 4 | C27: 461 | D27: 與俺情同嫡親兄弟 | E27: 俺以三兩五分紋銀收買 | F27: 改裝時直不下七兩 | G27: ●
A28: 27 | B28: 4 | C28: 462 | D28: 俺以三兩五分紋銀收買 | E28: 改裝時直不下七兩 | F28: 但無畵
A29: 28 | B29: 4 | C29: 469 | D29: 主人亦設酒果 | E29: 大約我國書畵 | F29: 什無年號
A30: 29 | B30: 4 | C30: 470 | D30: 大約我國書畵 | E30: 什無年號 | F30: 又不肯書名字 | G30: ●
A31: 30 | B31: 4 | C31: 471 | D31: 什無年號 | E31: 又不肯書名字 | F31: 詩軸所題
A32: 31 | B32: 4 | C32: 492 | D32: 故到處向人 | E32: 輒呼炒卵二字 | F32: 以試其舌頭利澀
A33: 32 | B33: 4 | C33: 493 | D33: 輒呼炒卵二字 | E33: 以試其舌頭利澀 | F33: 因此號鄭爲炒卵公 | G33: ●
A34: 33 | B34: 4 | C34: 494 | D34: 以試其舌頭利澀 | E34: 因此號鄭爲炒卵公 | F34: 我東優戱爲假面
A35: 34 | B35: 4 | C35: 502 | D35: 相與大笑 | E35: 備說其由 | F35: 欲贈其價
A36: 35 | B36: 4 | C36: 503 | D36: 備說其由 | E36: 欲贈其價 | F36: 主人大慚曰 | G36: ●
A37: 36 | B37: 4 | C37: 504 | D37: 欲贈其價 | E37: 主人大慚曰 | F37: 此非酒飯店
A38: 37 | B38: 36 | C38: 27 | D38: 朝氣微凉 | E38: 城外臨水開市 | F38: 百貨塡咽
A39: 38 | B39: 36 | C39: 28 | D39: 城外臨水開市 | E39: 百貨塡咽 | F39: 車馬縱橫 | G39: ●
A40: 39 | B40: 36 | C40: 29 | D40: 百貨塡咽 | E40: 車馬縱橫 | F40: 自入市中
...

Sheet 옥갑야화
A1: 연번 | B1: 문단 | C1: 절번호 | D1: 앞 절 | E1: 판정 대상 절 | F1: 뒤 절 | G1: 트리거 | H1: 은유 여부 | I1: 원천 영역 | J1: 목표 영역 | K1: 원천 어휘 | L1: 목표 개념 | M1: 판정 근거 | N1: 확신도 | O1: 비고
A2: 1 | B2: 2 | C2: 3 | D2: 與諸裨連牀夜語 | E2: 燕京舊時風俗淳厚 | F2: 譯輩雖萬金能相假貸
A3: 2 | B3: 2 | C3: 4 | D3: 燕京舊時風俗淳厚 | E3: 譯輩雖萬金能相假貸 | F3: 今則彼以欺詐爲能事 | G3: ●
A4: 3 | B4: 2 | C4: 5 | D4: 譯輩雖萬金能相假貸 | E4: 今則彼以欺詐爲能事 | F4: 而其
A5: 4 | B5: 2 | C5: 14 | D5: 對曰 | E5: 渡江 | F5: 時潛挾他人銀
A6: 5 | B6: 2 | C6: 15 | D6: 渡江 | E6: 時潛挾他人銀 | F6: 事發 | G6: ●
A7: 6 | B7: 2 | C7: 16 | D7: 時潛挾他人銀 | E7: 事發 | F7: 倂已包沒于官
A8: 7 | B8: 2 | C8: 24 | D8: 奪 | E8: 刀問曰 | F8: 所沒銀幾何
A9: 8 | B9: 2 | C9: 25 | D9: 刀問曰 | E9: 所沒銀幾何 | F9: 曰 | G9: ●
A10: 9 | B10: 2 | C10: 26 | D10: 所沒銀幾何 | E10: 曰 | F10: 三千兩
A11: 10 | B11: 2 | C11: 29 | D11: 主顧慰曰 | E11: 大丈夫獨患無身 | F11: 何患無銀
A12: 11 | B12: 2 | C12: 30 | D12: 大丈夫獨患無身 | E12: 何患無銀 | F12: 今死不還 | G12: ●
A13: 12 | B13: 2 | C13: 31 | D13: 何患無銀 | E13: 今死不還 | F13: 將如妻子何
A14: 13 | B14: 2 | C14: 33 | D14: 將如妻子何 | E14: 吾貸 | F14: 君萬金
A15: 14 | B15: 2 | C15: 34 | D15: 吾貸 | E15: 君萬金 | F15: 五年貨殖 | G15: ●
A16: 15 | B16: 2 | C16: 35 | D16: 君萬金 | E16: 五年貨殖 | F16: 可復得萬金 | G16: ●
A17: 16 | B17: 2 | C17: 36 | D17: 五年貨殖 | E17: 可復得萬金 | F17: 以本銀償我 | G17: ●
A18: 17 | B18: 2 | C18: 37 | D18: 可復得萬金 | E18: 以本銀償我 | F18: 譯旣得萬金 | G18: ●
A19: 18 | B19: 2 | C19: 38 | D19: 以本銀償我 | E19: 譯旣得萬金 | F19: 遂大貿而還 | G19: ●
A20: 19 | B20: 2 | C20: 39 | D20: 譯旣得萬金 | E20: 遂大貿而還 | F20: 當時未有識之者
A21: 20 | B21: 2 | C21: 41 | D21: 當時未有識之者 | E21: 莫不神其才 | F21: 五年中遂致鉅富
A22: 21 | B22: 2 | C22: 42 | D22: 莫不神其才 | E22: 五年中遂致鉅富 | F22: 乃自削籍譯院 | G22: ●
A23: 22 | B23: 2 | C23: 43 | D23: 五年中遂致鉅富 | E23: 乃自削籍譯院 | F23: 不復入燕
A24: 23 | B24: 3 | C24: 2 | D24: 有言李知事樞 | E24: 近世名譯也 | F24: 平居口未嘗言錢
A25: 24 | B25: 3 | C25: 3 | D25: 近世名譯也 | E25: 平居口未嘗言錢 | F25: 出入燕京四十餘年 | G25: ●
A26: 25 | B26: 3 | C26: 4 | D26: 平居口未嘗言錢 | E26: 出入燕京四十餘年 | F26: 手未嘗執銀
A27: 26 | B27: 3 | C27: 5 | D27: 出入燕京四十餘年 | E27: 手未嘗執銀 | F27: 有愷悌君子之風 | G27: ●
A28: 27 | B28: 3 | C28: 6 | D28: 手未嘗執銀 | E28: 有愷悌君子之風
A29: 28 | B29: 4 | C29: 5 | D29: 嘗遊娼館 | E29: 女隨色第 | F29: 價有千金者
A30: 29 | B30: 4 | C30: 6 | D30: 女隨色第 | E30: 價有千金者 | F30: 洪以千金求薦枕 | G30: ●
A31: 30 | B31: 4 | C31: 7 | D31: 價有千金者 | E31: 洪以千金求薦枕 | F31: 女 | G31: ●
A32: 31 | B32: 4 | C32: 8 | D32: 洪以千金求薦枕 | E32: 女 | F32: 方二八
A33: 32 | B33: 4 | C33: 11 | D33: 有殊色 | E33: 對君泣曰 | F33: 奴所以索高價者
A34: 33 | B34: 4 | C34: 12 | D34: 對君泣曰 | E34: 奴所以索高價者 | F34: 誠謂天下皆慳男 | G34: ●
A35: 34 | B35: 4 | C35: 13 | D35: 奴所以索高價者 | E35: 誠謂天下皆慳男 | F35: 無肯捐千金者
A36: 35 | B36: 4 | C36: 14 | D36: 誠謂天下皆慳男 | E36: 無肯捐千金者 | F36: 祈以免斯須之辱 | G36: ●
A37: 36 | B37: 4 | C37: 15 | D37: 無肯捐千金者 | E37: 祈以免斯須之辱 | F37: 一日
A38: 37 | B38: 4 | C38: 19 | D38: 本欲以愚館主 | E38: 一以望天下有義氣人 | F38: 贖奴作箕帚妾
A39: 38 | B39: 4 | C39: 20 | D39: 一以望天下有義氣人 | E39: 贖奴作箕帚妾 | F39: 奴入娼館五日 | G39: ●
A40: 39 | B40: 4 | C40: 21 | D40: 贖奴作箕帚妾 | E40: 奴入娼館五日 | F40: 無敢以千金來者
...

Sheet 행재잡록
A1: 연번 | B1: 문단 | C1: 절번호 | D1: 앞 절 | E1: 판정 대상 절 | F1: 뒤 절 | G1: 트리거 | H1: 은유 여부 | I1: 원천 영역 | J1: 목표 영역 | K1: 원천 어휘 | L1: 목표 개념 | M1: 판정 근거 | N1: 확신도 | O1: 비고
A2: 1 | B2: 2 | C2: 23 | D2: 故其所都燕京曰京師 | E2: 其巡幸之所曰行在 | F2: 我效土物之儀曰職貢
A3: 2 | B3: 2 | C3: 24 | D3: 其巡幸之所曰行在 | E3: 我效土物之儀曰職貢 | F3: 其語當宁曰天子 | G3: ●
A4: 3 | B4: 2 | C4: 25 | D4: 我效土物之儀曰職貢 | E4: 其語當宁曰天子 | F4: 其朝
A5: 4 | B5: 2 | C5: 36 | D5: 昔倭人覆我疆域 | E5: 我神宗皇帝提天下之師東援之 | F5: 竭帑銀以
A6: 5 | B6: 2 | C6: 37 | D6: 我神宗皇帝提天下之師東援之 | E6: 竭帑銀以 | F6: 供師旅 | G6: ●
A7: 6 | B7: 2 | C7: 38 | D7: 竭帑銀以 | E7: 供師旅 | F7: 復我三都
A8: 7 | B8: 2 | C8: 50 | D8: 所以加惠我國者 | E8: 亦累葉矣 | F8: 金非土產則蠲之
A9: 8 | B9: 2 | C9: 51 | D9: 亦累葉矣 | E9: 金非土產則蠲之 | F9: 綵馬衰小則 | G9: ●
A10: 9 | B10: 2 | C10: 52 | D10: 金非土產則蠲之 | E10: 綵馬衰小則 | F10: 免之
A11: 10 | B11: 2 | C11: 64 | D11: 命班于大臣之列 | E11: 其聽戱得比廷臣而宴賚之 | F11: 又詔永蠲正貢外
A12: 11 | B12: 2 | C12: 65 | D12: 其聽戱得比廷臣而宴賚之 | E12: 又詔永蠲正貢外 | F12: 別使方物 | G12: ●
A13: 12 | B13: 2 | C13: 66 | D13: 又詔永蠲正貢外 | E13: 別使方物 | F13: 此實曠世盛典
A14: 13 | B14: 2 | C14: 84 | D14: 在大國不過爲卹小 | E14: 柔遠之政 | F14: 則雖代蠲一貢
A15: 14 | B15: 2 | C15: 85 | D15: 柔遠之政 | E15: 則雖代蠲一貢 | F15: 歲免一幣 | G15: ●
A16: 15 | B16: 2 | C16: 86 | D16: 則雖代蠲一貢 | E16: 歲免一幣 | F16: 是惠也
A17: 16 | B17: 8 | C17: 6 | D17: 會同理藩院司員等帶領朝鮮使臣正使朴副使鄭書 | E17: 狀官趙等 | F17: 前詣札什倫布
A18: 17 | B18: 8 | C18: 7 | D18: 狀官趙等 | E18: 前詣札什倫布 | F18: 拜見額爾德尼 | G18: ●
A19: 18 | B19: 8 | C19: 8 | D19: 前詣札什倫布 | E19: 拜見額爾德尼 | F19: 行禮後
A20: 19 | B20: 8 | C20: 11 | D20: 令坐吃茶 | E20: 詢問該國遠近 | F20: 幷入貢緣由
A21: 20 | B21: 8 | C21: 12 | D21: 詢問該國遠近 | E21: 幷入貢緣由 | F21: 該使臣答以 | G21: ●
A22: 21 | B22: 8 | C22: 13 | D22: 幷入貢緣由 | E22: 該使臣答以 | F22: 因皇上七旬大慶
A23: 22 | B23: 9 | C23: 2 | D23: 使臣見班禪事 | E23: 余具載之 | F23: 札什倫布記及見禮部奏聞
A24: 23 | B24: 9 | C24: 3 | D24: 余具載之 | E24: 札什倫布記及見禮部奏聞 | F24: 其稱拜見額爾德尼 | G24: ●
A25: 24 | B25: 9 | C25: 4 | D25: 札什倫布記及見禮部奏聞 | E25: 其稱拜見額爾德尼 | F25: 給與使臣等物件
A26: 25 | B26: 9 | C26: 11 | D26: 不得不爾 | E26: 第據吾所目擊者詳錄之 | F26: 以資山中曝背一粲
A27: 26 | B27: 9 | C27: 12 | D27: 第據吾所目擊者詳錄之 | E27: 以資山中曝背一粲 | F27: 覽者 | G27: ●
A28: 27 | B28: 9 | C28: 13 | D28: 以資山中曝背一粲 | E28: 覽者 | F28: 當有以察之
A29: 28 | B29: 13 | C29: 4 | D29: 中國例相贈遺遠遊者 | E29: 必持此朝夕供養 | F29: 藏俗年例進貢
A30: 29 | B30: 13 | C30: 5 | D30: 必持此朝夕供養 | E30: 藏俗年例進貢 | F30: 首以佛一尊爲 | G30: ●
A31: 30 | B31: 13 | C31: 6 | D31: 藏俗年例進貢 | E31: 首以佛一尊爲 | F31: 方物
A32: 31 | B32: 13 | C32: 18 | D32: 諸譯亦視同糞穢 | E32: 若將凂焉 | F32: 售銀九十兩
A33: 32 | B33: 13 | C33: 19 | D33: 若將凂焉 | E33: 售銀九十兩 | F33: 散之一行 | G33: ●
A34: 33 | B34: 13 | C34: 20 | D34: 售銀九十兩 | E34: 散之一行 | F34: 馬頭輩
A35: 34 | B35: 13 | C35: 21 | D35: 散之一行 | E35: 馬頭輩 | F35: 而不以此銀
A36: 35 | B36: 13 | C36: 22 | D36: 馬頭輩 | E36: 而不以此銀 | F36: 沽飮一盃酒 | G36: ●
A37: 36 | B37: 13 | C37: 23 | D37: 而不以此銀 | E37: 沽飮一盃酒 | F37: 潔則潔矣
A38: 37 | B38: 16 | C38: 3 | D38: 稱乾隆四十五年八月十二日內閣奉上諭朝鮮世守藩封 | E38: 素稱恭順 | F38: 歲時職貢
A39: 38 | B39: 16 | C39: 4 | D39: 素稱恭順 | E39: 歲時職貢 | F39: 祗愼可嘉 | G39: ●
A40: 39 | B40: 16 | C40: 5 | D40: 歲時職貢 | E40: 祗愼可嘉 | F40: 間遇特頒敕諭及資送歸國等事
...

Sheet 심세편
A1: 연번 | B1: 문단 | C1: 절번호 | D1: 앞 절 | E1: 판정 대상 절 | F1: 뒤 절 | G1: 트리거 | H1: 은유 여부 | I1: 원천 영역 | J1: 목표 영역 | K1: 원천 어휘 | L1: 목표 개념 | M1: 판정 근거 | N1: 확신도 | O1: 비고
A2: 1 | B2: 2 | C2: 22 | D2: 道 | E2: 逢御史汪道昆 | F2: 屛息路左
A3: 2 | B3: 2 | C3: 23 | D3: 逢御史汪道昆 | E3: 屛息路左 | F3: 瞻望行塵 | G3: ●
A4: 3 | B4: 2 | C4: 24 | D4: 屛息路左 | E4: 瞻望行塵 | F4: 猶以爲榮
A5: 4 | B5: 2 | C5: 109 | D5: 始知衣冠士族幷在中原 | E5: 禮儀 | F5: 富盛
A6: 5 | B6: 2 | C6: 110 | D6: 禮儀 | E6: 富盛 | F6: 人物殷阜 | G6: ●
A7: 6 | B7: 2 | C7: 111 | D7: 富盛 | E7: 人物殷阜 | F7: 耳目所識
A8: 7 | B8: 2 | C8: 131 | D8: 等百世之王 | E8: 莫之能違也 | F8: 旣無子貢之藝
A9: 8 | B9: 2 | C9: 132 | D9: 莫之能違也 | E9: 旣無子貢之藝 | F9: 季札之智 | G9: ●
A10: 9 | B10: 2 | C10: 133 | D10: 旣無子貢之藝 | E10: 季札之智 | F10: 則雖使笙鏞干
A11: 10 | B11: 2 | C11: 238 | D11: 也 | E11: 彼將曰 | F11: 吾非利天下也
A12: 11 | B12: 2 | C12: 239 | D12: 彼將曰 | E12: 吾非利天下也 | F12: 吾爲明室 | G12: ●
A13: 12 | B13: 2 | C13: 240 | D13: 吾非利天下也 | E13: 吾爲明室 | F13: 復大仇雪大恥
A14: 13 | B14: 2 | C14: 288 | D14: 似若無所用心 | E14: 然其心以爲天下之小民 | F14: 薄其賦斂則安矣
A15: 14 | B15: 2 | C15: 289 | D15: 然其心以爲天下之小民 | E15: 薄其賦斂則安矣 | F15: 安知不 | G15: ●
A16: 15 | B16: 2 | C16: 290 | D16: 薄其賦斂則安矣 | E16: 安知不 | F16: 反便乎我之帽服而不欲變我之制度乎
A17: 16 | B17: 2 | C17: 296 | D17: 心 | E17: 其豪傑敢怒而不敢言其鄙佞 | F17: 因時義而爲身利
A18: 17 | B18: 2 | C18: 297 | D18: 其豪傑敢怒而不敢言其鄙佞 | E18: 因時義而爲身利 | F18: 一以陰弱中土之士 | G18: ●
A19: 18 | B19: 2 | C19: 298 | D19: 因時義而爲身利 | E19: 一以陰弱中土之士 | F19: 一以顯受文敎之名
A20: 19 | B20: 2 | C20: 328 | D20: 皇帝私尊何累朱子 | E20: 而中州之士如此其恥之者 | F20: 葢有所激於陽尊而爲禦世之資耳
A21: 20 | B21: 2 | C21: 329 | D21: 而中州之士如此其恥之者 | E21: 葢有所激於陽尊而爲禦世之資耳 | F21: 故時借一二集註之誤 | G21: ●
A22: 21 | B22: 2 | C22: 330 | D22: 葢有所激於陽尊而爲禦世之資耳 | E22: 故時借一二集註之誤 | F22: 以洩百年煩寃之氣

Sheet 코드 정의
A1: 구분 | B1: 코드 | C1: 정의
A2: 원천 영역 | B2: SD-1 자연·물질 | C2: 물·지형·광물·기상 등 자연물과 그 운동
A3: 원천 영역 | B3: SD-2 신체·감각 | C3: 신체 부위와 그 작용, 감각 경험
A4: 원천 영역 | B4: SD-3 공간·방위 | C4: 상하·내외·원근 등 공간 배치와 방위
A5: 원천 영역 | B5: SD-4 사냥·전쟁 | C5: 목표물을 두고 경쟁적으로 추격·획득하는 행위
A6: 원천 영역 | B6: SD-5 운동·시간 | C6: 이동·방향·시간의 경과와 축적
A7: 원천 영역 | B7: SD-6 문화·제도 | C7: 역사 인물·전거, 신분 제도, 문자·복식 등 인공적 산물
A8: 원천 영역 | B8: (수사 기제) | C8: 원천 영역이 아니라 과장·역설·대조 등 표현을 조직하는 방식
A9: 목표 영역 | B9: TD-1 축적·유통 | C9: 재화의 축적, 유통, 경제 원리 자체
A10: 목표 영역 | B10: TD-2 권력·지배 | C10: 정치 권력, 지배와 복속, 국가 간 관계
A11: 목표 영역 | B11: TD-3 인식·진위 | C11: 앎, 판단, 진위 분별, 인식의 한계
A12: 목표 영역 | B12: TD-4 도덕·책무 | C12: 윤리 규범, 의무, 사회적 책임
... A15: 목표 영역 | B15: TD-6 기타 | C15: 위 여섯에 들지 않는 목표. 반드시 비고란에 무엇인지 적을 것
