Workbook

Sheet 시작하기 전에
A1: 항목 | B1: 내용
A2: 판정자 | B2: 판정자 2 — 이 파일은 판정자 본인 전용 사본입니다. 다른 판정자의 파일을 열지 마십시오.
A3: 이 작업의 성격 | B3: 두 판정자가 같은 자료를 서로 보지 않고 각자 판정한 뒤, 두 결과의 일치도를 Cohen's Kappa로 산출합니다. 판정이 개인의 자의가 아니라 공유 가능한 기준에 따른 것임을 보이기 위한 절차입니다. 연구자 본인은 판정에 참여하지 않고 불일치 항목의 조정만 맡습니다.
A4: 작업 범위 | B4: 「화식열전」 394절과 「도강록」 324절, 합계 718절이 필수입니다. 이 두 편은 기존 판정 자료가 남아 있지 않아 이번 검증의 핵심입니다. 나머지 6편은 여력이 되면 진행하시고 못 하셔도 무방합니다. 「진행 현황」 시트에 우선순위를 표시해 두었습니다.
A5: 보조 자료 | B5: 원문 옆에 주요 글자의 기본 의미(초록)와 직역·의역(보라·주황)을 붙여 두었습니다. 이 번역은 인공지능이 작성한 초벌이며 연구자의 검수를 거치지 않았습니다. 참고로만 쓰시고, 번역과 원문에 대한 판단이 엇갈리면 반드시 원문을 따르고 비고란에 그 사실을 적어 주십시오. 오역을 발견하시면 비고란에 알려 주시면 고맙겠습니다.
A6: 가장 중요한 규칙 | B6: 파란 칸 「★ 판정 대상 절 ★」만 판정합니다. 좌우 회색 칸은 뜻을 이해하기 위한 문맥일 뿐이며, 거기에 은유가 보여도 이 행에 적으면 안 됩니다. 그 절은 별도의 행으로 따로 나옵니다.
A7: 입력 순서 | B7: ① 은유 여부(Y/N) → ② Y이면 원천 영역·목표 영역 → ③ 원천 어휘·목표 개념 → ④ 판정 근거 한 줄 → ⑤ 확신도
A8: N도 반드시 입력 | B8: 은유가 아닌 절도 N으로 표시해야 합니다. 빈칸으로 두면 미판정과 구별되지 않아 일치도를 계산할 수 없습니다. 이 점이 이번 재코딩의 핵심입니다.
A9: 절당 1건 | B9: 한 절에 은유가 둘 이상이면 대표 하나만 판정하고 나머지는 비고란에 적으십시오. 두 판정자의 단위가 어긋나면 대조가 불가능해집니다.
A10: 판정 방법 | B10: ① 그 어휘의 기본 의미(더 구체적이고 신체적 경험에 가까우며 역사적으로 앞선 의미)를 떠올립니다. ② 여기서 쓰인 뜻이 그것과 다른지 봅니다. ③ 다르고, 앞의 것을 뒤의 것과의 비교로 이해할 수 있으면 Y입니다. ④ Y이면 원천이 어느 영역에서 왔는지, 무엇을 말하려 하는지를 각각 고릅니다.
A11: 원천을 보십시오 | B11: 가장 흔한 실수는 목표를 보고 원천 영역을 고르는 것입니다. 厚生은 목표가 삶의 윤택함이지만 원천은 두께이므로 SD-3 공간·방위입니다. 貧瘁는 목표가 민생이지만 원천은 병듦이므로 SD-2 신체·감각입니다.
A12: 과장·역설 | B12: 두 영역 사이의 사상이 아니므로 원천 영역이 아닙니다. 그것만으로 된 표현은 원천 영역에 「(수사 기제)」를 고르십시오. 怖殺·魂飛九霄雲外 등이 그렇습니다.
... A18: 판정 근거를 꼭 | B18: 귀찮아 보이지만 이것이 가장 효율적입니다. 같은 어휘를 다시 만났을 때 찾아 쓸 수 있고, 조정 단계에서 왜 그렇게 보았는지 설명할 수 있습니다.

Sheet 진행 현황
A1: 텍스트 | B1: 판정 대상 절 | C1: 판정 완료 | D1: 미판정 | E1: 은유(Y) | F1: 비은유(N) | G1: 우선순위 | H1: 번역 제공
A2: 화식열전 | B2: 394 | C2: =COUNTIF(화식열전!$K$2:$K$395,"Y")+COUNTIF(화식열전!$K$2:$K$395,"N") -> 394 | D2: =B2-C2 -> 0 | E2: =COUNTIF(화식열전!$K$2:$K$395,"Y") -> 73 | F2: =COUNTIF(화식열전!$K$2:$K$395,"N") -> 321 | G2: 필수 | H2: 있음
A3: 도강록 | B3: 324 | C3: =COUNTIF(도강록!$K$2:$K$325,"Y")+COUNTIF(도강록!$K$2:$K$325,"N") -> 324 | D3: =B3-C3 -> 0 | E3: =COUNTIF(도강록!$K$2:$K$325,"Y") -> 30 | F3: =COUNTIF(도강록!$K$2:$K$325,"N") -> 294 | G3: 필수 | H3: 있음
A4: 성경잡지 | B4: 295 | C4: =COUNTIF(성경잡지!$I$2:$I$296,"Y")+COUNTIF(성경잡지!$I$2:$I$296,"N") -> 295 | D4: =B4-C4 -> 0 | E4: =COUNTIF(성경잡지!$I$2:$I$296,"Y") -> 24 | F4: =COUNTIF(성경잡지!$I$2:$I$296,"N") -> 271 | G4: 여력 시 | H4: 없음
A5: 일신수필 | B5: 273 | C5: =COUNTIF(일신수필!$I$2:$I$274,"Y")+COUNTIF(일신수필!$I$2:$I$274,"N") -> 273 | D5: =B5-C5 -> 0 | E5: =COUNTIF(일신수필!$I$2:$I$274,"Y") -> 29 | F5: =COUNTIF(일신수필!$I$2:$I$274,"N") -> 244 | G5: 여력 시 | H5: 없음
A6: 관내정사 | B6: 254 | C6: =COUNTIF(관내정사!$I$2:$I$255,"Y")+COUNTIF(관내정사!$I$2:$I$255,"N") -> 254 | D6: =B6-C6 -> 0 | E6: =COUNTIF(관내정사!$I$2:$I$255,"Y") -> 27 | F6: =COUNTIF(관내정사!$I$2:$I$255,"N") -> 227 | G6: 여력 시 | H6: 없음
A7: 옥갑야화 | B7: 254 | C7: =COUNTIF(옥갑야화!$K$2:$K$255,"Y")+COUNTIF(옥갑야화!$K$2:$K$255,"N") -> 254 | D7: =B7-C7 -> 0 | E7: =COUNTIF(옥갑야화!$K$2:$K$255,"Y") -> 40 | F7: =COUNTIF(옥갑야화!$K$2:$K$255,"N") -> 214 | G7: 여력 시 | H7: 있음
A8: 행재잡록 | B8: 65 | C8: =COUNTIF(행재잡록!$K$2:$K$66,"Y")+COUNTIF(행재잡록!$K$2:$K$66,"N") -> 65 | D8: =B8-C8 -> 0 | E8: =COUNTIF(행재잡록!$K$2:$K$66,"Y") -> 10 | F8: =COUNTIF(행재잡록!$K$2:$K$66,"N") -> 55 | G8: 여력 시 | H8: 있음
A9: 심세편 | B9: 21 | C9: =COUNTIF(심세편!$K$2:$K$22,"Y")+COUNTIF(심세편!$K$2:$K$22,"N") -> 21 | D9: =B9-C9 -> 0 | E9: =COUNTIF(심세편!$K$2:$K$22,"Y") -> 8 | F9: =COUNTIF(심세편!$K$2:$K$22,"N") -> 13 | G9: 여력 시 | H9: 있음
A10: 합계 | B10: =SUM(B2:B9) -> 1880 | C10: =SUM(C2:C9) -> 1880 | D10: =SUM(D2:D9) -> 0 | E10: =SUM(E2:E9) -> 241 | F10: =SUM(F2:F9) -> 1639
A12: ※ 번역이 없는 3편(성경잡지·일신수필·관내정사)은 원문과 어휘 주석만으로 판정하시면 됩니다. 필수 범위인 화식열전·도강록에는 번역이 모두 있습니다.

Sheet 화식열전
A1: 연번 | B1: 문단 | C1: 절번호 | D1: 앞 문맥(참고) | E1: ★ 판정 대상 절 ★ | F1: 뒤 문맥(참고) | G1: 트리거 | H1: 주요 글자의 기본 의미 | I1: 직역 | J1: 의역 | K1: 은유 여부 | L1: 원천 영역 | M1: 목표 영역 | N1: 원천 어휘 | O1: 목표 개념 | P1: 판정 근거 | Q1: 확신도 | R1: 비고
A2: 1 | B2: 2 | C2: 13 | D2: 終不能化 | E2: 故善者因之 | F2: 其次利道之 | H2: 故=까닭 · 善=착하다 · 者=~하는 것·사람 · 因=말미암다 · 之=가다 (조사로도 쓰임) | I2: 그러므로 잘하는 자는 그것을 따른다 | J2: 가장 나은 정치는 백성이 하는 대로 두는 것이다 | K2: N | Q2: 보통
A3: 2 | B3: 2 | C3: 14 | D3: 故善者因之 | E3: 其次利道之 | F3: 其次教誨之 | G3: 利 | H3: 其=그 · 利=날이 날카롭다 → 이롭다 · 道=길 · 之=가다 (조사로도 쓰임) | I3: 그다음은 이롭게 하여 이끈다 | J3: 그다음은 이익으로 유도하는 것이다 | K3: Y | L3: SD-3 공간·방위 | M3: TD-1 축적·유통 | N3: 道 | O3: 인도 | P3: 길이 백성을 이끄는 방도로 옮겨감 | Q3: 보통
A4: 3 | B4: 2 | C4: 15 | D4: 其次利道之 | E4: 其次教誨之 | F4: 其次整齊之 | H4: 其=그 · 之=가다 (조사로도 쓰임) | I4: 그다음은 가르쳐 깨우친다 | J4: 그다음은 가르쳐 인도하는 것이다 | K4: N | Q4: 보통
A5: 4 | B5: 3 | C5: 38 | D5: 虞而出之 | E5: 工而成之 | F5: 商而通之 | H5: 工=장인 · 而=말 잇는 조사 · 成=이루다 · 之=가다 (조사로도 쓰임) | I5: 장인이 그것을 만들어 낸다 | J5: 장인이 물건으로 완성한다 | K5: N | Q5: 보통
A6: 5 | B6: 3 | C6: 39 | D6: 工而成之 | E6: 商而通之 | F6: 此寧有政教發徵期會哉 | G6: 商 | H6: 商=장사하다 · 而=말 잇는 조사 · 通=통하다 · 之=가다 (조사로도 쓰임) | I6: 상인이 그것을 통하게 한다 | J6: 상인이 그것을 유통시킨다 | K6: Y | L6: SD-3 공간·방위 | M6: TD-1 축적·유통 | N6: 通 | O6: 유통 | P6: 길이 통함이 재화의 소통으로 옮겨감 | Q6: 높음
A7: 6 | B7: 3 | C7: 40 | D7: 商而通之 | E7: 此寧有政教發徵期會哉 | F7: 人各任其能 | H7: 此=이것 · 有=있다 | I7: 이것이 어찌 정령과 교화로 불러 모은 것이겠는가 | J7: 이것이 관청이 명령해서 된 일이겠는가 | K7: N | Q7: 보통
A8: 7 | B8: 4 | C8: 3 | D8: 農不出則乏其食 | E8: 工不出則乏其事 | F8: 商不出則三寶絕 | H8: 工=장인 · 不=아니다 · 出=나가다 · 則=곧 · 其=그 · 事=일 | I8: 장인이 나오지 않으면 그 일이 모자란다 | J8: 장인이 없으면 기물이 부족해진다 | K8: N | Q8: 보통
A9: 8 | B9: 4 | C9: 4 | D9: 工不出則乏其事 | E9: 商不出則三寶絕 | F9: 虞不出則財匱少 | G9: 商 | H9: 商=장사하다 · 不=아니다 · 出=나가다 · 則=곧 · 三=셋 · 絕=실을 끊다 | I9: 상인이 나오지 않으면 세 가지 보배가 끊어진다 | J9: 상인이 없으면 식량·기물·재화가 끊긴다 | K9: Y | L9: SD-6 문화·제도 | M9: TD-1 축적·유통 | N9: 絕 | O9: 단절 | P9: 줄이 끊김이 물자 공급의 두절로 옮겨감 | Q9: 보통
A10: 9 | B10: 4 | C10: 5 | D10: 商不出則三寶絕 | E10: 虞不出則財匱少 | F10: 財匱 | G10: 財 | H10: 不=아니다 · 出=나가다 · 則=곧 · 財=재물 · 少=적다 | I10: 산택 맡은 이가 나오지 않으면 재물이 모자라 적어진다 | J10: 산림과 늪을 맡은 이가 없으면 물자가 줄어든다 | K10: N | Q10: 보통
A11: 10 | B11: 4 | C11: 6 | D11: 虞不出則財匱少 | E11: 財匱 | F11: 少而山澤不辟矣 | G11: 財 | H11: 財=재물 | I11: 재물이 모자란다 | J11: 물자가 바닥난다 | K11: N | Q11: 보통
A12: 11 | B12: 4 | C12: 7 | D12: 財匱 | E12: 少而山澤不辟矣 | F12: 此四者 | H12: 少=적다 · 而=말 잇는 조사 · 山=산 · 不=아니다 · 矣=마치는 조사 | I12: 적어지면 산과 못이 열리지 않는다 | J12: 물자가 줄면 산림과 늪이 개발되지 않는다 | K12: Y | L12: SD-3 공간·방위 | M12: TD-1 축적·유통 | N12: 辟 | O12: 개발 | P12: 문을 엶이 산택의 개발로 옮겨감 | Q12: 낮음
A13: 12 | B13: 4 | C13: 11 | D13: 原大則饒 | E13: 原小則鮮 | F13: 上則富國 | H13: 原=물의 발원지 · 小=작다 · 則=곧 | I13: 근원이 작으면 드물다 | J13: 밑천이 적으면 소출도 적다 | K13: Y | L13: SD-1 자연·물질 | M13: TD-1 축적·유통 | N13: 原 | O13: 근원 | P13: 물의 발원지가 재화의 원천으로 옮겨감 | Q13: 높음
A14: 13 | B14: 4 | C14: 12 | D14: 原小則鮮 | E14: 上則富國 | F14: 下則富家 | G14: 富 | H14: 上=위쪽 · 則=곧 · 富=재물이 넉넉하다 · 國=나라 | I14: 위로는 나라를 부유하게 한다 | J14: 크게는 나라를 부강하게 한다 | K14: Y | L14: SD-3 공간·방위 | M14: TD-5 문명·제도 | N14: 上 | O14: 국가 | P14: 공간의 위가 국가 층위로 옮겨감 | Q14: 보통
A15: 14 | B15: 4 | C15: 13 | D15: 上則富國 | E15: 下則富家 | F15: 貧富 | G15: 富 | H15: 下=아래쪽 · 則=곧 · 富=재물이 넉넉하다 · 家=집 | I15: 아래로는 집을 부유하게 한다 | J15: 작게는 집안을 넉넉하게 한다 | K15: Y | L15: SD-3 공간·방위 | M15: TD-5 문명·제도 | N15: 下 | O15: 민가 | P15: 공간의 아래가 민간 층위로 옮겨감 | Q15: 보통
A16: 15 | B16: 4 | C16: 14 | D16: 下則富家 | E16: 貧富 | F16: 之道 | G16: 富 貧 | H16: 貧=재물이 모자라다 · 富=재물이 넉넉하다 | I16: 가난함과 부유함 | J16: 빈부라는 것은 | K16: N | Q16: 보통
A17: 16 | B17: 4 | C17: 15 | D17: 貧富 | E17: 之道 | F17: 莫之奪予 | H17: 之=가다 (조사로도 쓰임) · 道=길 | I17: ~의 이치 | J17: 그 이치는 | K17: Y | L17: SD-3 공간·방위 | M17: TD-1 축적·유통 | N17: 道 | O17: 이치 | P17: 길이 빈부의 원리로 옮겨감 | Q17: 높음
A18: 17 | B18: 4 | C18: 39 | D18: 歸 | E18: 位在陪臣 | F18: 富於列國之君 | H18: 在=있다 · 臣=신하 | I18: 지위는 배신에 있었다 | J18: 신분은 제후의 신하에 지나지 않았으나 | K18: N | Q18: 보통
A19: 18 | B19: 4 | C19: 40 | D19: 位在陪臣 | E19: 富於列國之君 | F19: 是以齊富彊至於威 | G19: 富 | H19: 富=재물이 넉넉하다 · 於=~에 · 國=나라 · 之=가다 (조사로도 쓰임) · 君=임금·그대 | I19: 여러 나라의 임금보다 부유했다 | J19: 제후들보다 더 부유했다 | K19: N | Q19: 보통
A20: 19 | B20: 4 | C20: 41 | D20: 富於列國之君 | E20: 是以齊富彊至於威 | F20: 宣也 | G20: 富 | H20: 是=옳다·이것 · 以=~로써 · 富=재물이 넉넉하다 · 至=이르다 · 於=~에 | I20: 이로써 제나라는 부강하여 위왕에 이르렀다 | J20: 그래서 제나라는 부강해져 위왕 때까지 이어졌다 | K20: N | Q20: 보통
A21: 20 | B21: 4 | C21: 42 | D21: 是以齊富彊至於威 | E21: 宣也 | H21: 也=단정하는 조사 | I21: 선왕이다 | J21: 선왕 대에 이르렀다 | K21: N | Q21: 보통
A22: 21 | B22: 5 | C22: 4 | D22: 衣食足而知榮辱 | E22: 禮生於有而廢於無 | F22: 故君子富 | H22: 禮=예 · 生=낳다·살다 · 於=~에 · 有=있다 · 而=말 잇는 조사 · 廢=그만두다 · 無=없다 | I22: 예는 있음에서 생기고 없음에서 폐한다 | J22: 예의는 살림이 있어야 생기고 없으면 사라진다 | K22: Y | L22: SD-1 자연·물질 | M22: TD-4 도덕·책무 | N22: 生·廢 | O22: 예의 발생 | P22: 초목이 나고 시듦이 예의 성쇠로 옮겨감 | Q22: 보통 | R22: 生·廢가 한 절 안에 함께 나타남
A23: 22 | B23: 5 | C23: 5 | D23: 禮生於有而廢於無 | E23: 故君子富 | F23: 好行其德 | G23: 富 | H23: 故=까닭 · 君=임금·그대 · 子=아들 · 富=재물이 넉넉하다 | I23: 그러므로 군자가 부유하면 | J23: 그러므로 군자는 부유해지면 | K23: N | Q23: 보통
A24: 23 | B24: 5 | C24: 6 | D24: 故君子富 | E24: 好行其德 | F24: 小人 | H24: 好=좋다 · 行=걸어가다 · 其=그 · 德=덕 | I24: 그 덕을 행하기를 좋아한다 | J24: 기꺼이 덕을 베푼다 | K24: Y | L24: SD-5 운동·시간 | M24: TD-4 도덕·책무 | N24: 行 | O24: 덕의 실행 | P24: 걸음이 덕의 실천으로 옮겨감 | Q24: 보통
A25: 24 | B25: 5 | C25: 7 | D25: 好行其德 | E25: 小人 | F25: 富 | H25: 小=작다 · 人=사람 | I25: 소인은 | J25: 소인은 | K25: N | Q25: 보통
A26: 25 | B26: 5 | C26: 8 | D26: 小人 | E26: 富 | F26: 以適其力 | G26: 富 | H26: 富=재물이 넉넉하다 | I26: 부유하면 | J26: 부유해지면 | K26: N | Q26: 보통
A27: 26 | B27: 5 | C27: 9 | D27: 富 | E27: 以適其力 | F27: 淵深而魚生之 | H27: 以=~로써 · 其=그 · 力=힘 | I27: 그 힘에 맞게 쓴다 | J27: 제 분수껏 쓴다 | K27: N | Q27: 보통
A28: 27 | B28: 5 | C28: 11 | D28: 淵深而魚生之 | E28: 山深而獸往之 | F28: 人富而仁義附焉 | H28: 山=산 · 深=깊다 · 而=말 잇는 조사 · 往=가다 · 之=가다 (조사로도 쓰임) | I28: 산이 깊으면 짐승이 그리로 간다 | J28: 산이 깊어야 짐승이 모여들듯 | K28: Y | L28: SD-3 공간·방위 | M28: TD-4 도덕·책무 | N28: 深 | O28: 부의 크기 | P28: 못과 산의 깊이가 부의 크기로 옮겨감(직유) | Q28: 높음
A29: 28 | B29: 5 | C29: 12 | D29: 山深而獸往之 | E29: 人富而仁義附焉 | F29: 富者得埶益彰 | G29: 富 | H29: 人=사람 · 富=재물이 넉넉하다 · 而=말 잇는 조사 · 仁=어짊 · 義=옳음 · 焉=어찌 | I29: 사람이 부유하면 인의가 거기에 붙는다 | J29: 사람이 부유해야 인의도 따라붙는다 | K29: N | Q29: 보통
A30: 29 | B30: 5 | C30: 13 | D30: 人富而仁義附焉 | E30: 富者得埶益彰 | F30: 失埶則客無所 | G30: 富 | H30: 富=재물이 넉넉하다 · 者=~하는 것·사람 · 得=얻다 · 益=더하다 | I30: 부유한 자는 세력을 얻어 더욱 드러난다 | J30: 부유하면 세력을 얻어 이름이 더 나고 | K30: Y | L30: SD-3 공간·방위 | M30: TD-1 축적·유통 | N30: 埶 | O30: 형세 | P30: 공간적 형세가 부의 지위로 옮겨감 | Q30: 보통
A31: 30 | B31: 5 | C31: 14 | D31: 富者得埶益彰 | E31: 失埶則客無所 | F31: 之 | H31: 失=잃다 · 則=곧 · 客=손님 · 無=없다 · 所=바·곳 | I31: 세력을 잃으면 객이 갈 곳이 없다 | J31: 세력을 잃으면 따르던 이들이 흩어진다 | K31: N | Q31: 보통
A32: 31 | B32: 5 | C32: 18 | D32: 夷狄益甚 | E32: 諺曰 | F32: 千金之子 | H32: 曰=말하다 | I32: 속담에 이르기를 | J32: 속담에 이런 말이 있다 | K32: N | Q32: 보통
A33: 32 | B33: 5 | C33: 19 | D33: 諺曰 | E33: 千金之子 | F33: 不死於市 | G33: 千金 | H33: 千=일천 · 金=쇠붙이 · 之=가다 (조사로도 쓰임) · 子=아들 | I33: 천금을 가진 집 자식은 | J33: 큰 부자의 자식은 | K33: N | Q33: 보통
A34: 33 | B34: 5 | C34: 20 | D34: 千金之子 | E34: 不死於市 | F34: 此非空言也 | H34: 不=아니다 · 死=죽다 · 於=~에 · 市=저자 | I34: 저자에서 죽지 않는다 | J34: 저자에서 처형당하는 일이 없다 | K34: N | Q34: 보통
A35: 34 | B35: 5 | C35: 23 | D35: 故曰 | E35: 天下熙熙 | F35: 皆為利來 | H35: 天=하늘 · 下=아래쪽 | I35: 천하가 북적북적하다 | J35: 천하가 시끌벅적한데 | K35: N | Q35: 보통
A36: 35 | B36: 5 | C36: 24 | D36: 天下熙熙 | E36: 皆為利來 | F36: 天下壤壤 | G36: 利 | H36: 皆=모두 · 為=하다 · 利=날이 날카롭다 → 이롭다 · 來=오다 | I36: 모두 이익을 위해 온다 | J36: 모두 이익을 좇아 몰려드는 것이다 | K36: Y | L36: SD-5 운동·시간 | M36: TD-1 축적·유통 | N36: 來 | O36: 이익의 쏠림 | P36: 오고 감이 이익 추구로 옮겨감 | Q36: 높음
A37: 36 | B37: 5 | C37: 25 | D37: 皆為利來 | E37: 天下壤壤 | F37: 皆為利往 | H37: 天=하늘 · 下=아래쪽 | I37: 천하가 어수선하다 | J37: 천하가 어지러운데 | K37: N | Q37: 보통
A38: 37 | B38: 5 | C38: 26 | D38: 天下壤壤 | E38: 皆為利往 | F38: 夫千乘之王 | G38: 利 | H38: 皆=모두 · 為=하다 · 利=날이 날카롭다 → 이롭다 · 往=가다 | I38: 모두 이익을 위해 간다 | J38: 모두 이익을 좇아 떠나는 것이다 | K38: Y | L38: SD-5 운동·시간 | M38: TD-1 축적·유통 | N38: 往 | O38: 이익의 쏠림 | P38: 오고 감이 이익 추구로 옮겨감 | Q38: 높음
A39: 38 | B39: 5 | C39: 27 | D39: 皆為利往 | E39: 夫千乘之王 | F39: 萬家之侯 | H39: 夫=사내·무릇 · 千=일천 · 之=가다 (조사로도 쓰임) · 王=임금 | I39: 무릇 천승의 왕 | J39: 수레 천 대를 거느린 왕이나 | K39: N | Q39: 보통
A40: 39 | B40: 5 | C40: 29 | D40: 萬家之侯 | E40: 百室之君 | F40: 尚猶患貧 | H40: 百=일백 · 之=가다 (조사로도 쓰임) · 君=임금·그대 | I40: 백실의 임금도 | J40: 백 채의 봉읍을 가진 이도 | K40: N | Q40: 보통
...

Sheet 도강록
A1: 연번 | B1: 문단 | C1: 절번호 | D1: 앞 문맥(참고) | E1: ★ 판정 대상 절 ★ | F1: 뒤 문맥(참고) | G1: 트리거 | H1: 주요 글자의 기본 의미 | I1: 직역 | J1: 의역 | K1: 은유 여부 | L1: 원천 영역 | M1: 목표 영역 | N1: 원천 어휘 | O1: 목표 개념 | P1: 판정 근거 | Q1: 확신도 | R1: 비고
A2: 1 | B2: 7 | C2: 10 | D2: 徐往舘所 | E2: 諸裨已著軍服戰笠矣 | F2: 頂起銀花雲月 | H2: 諸=여러 · 已=이미 · 服=옷 · 矣=마치는 조사 | I2: 여러 비장이 이미 군복과 전립을 입었다 | J2: 비장들은 벌써 군복에 전립을 갖추었고 | K2: N | Q2: 보통
A3: 2 | B3: 7 | C3: 11 | D3: 諸裨已著軍服戰笠矣 | E3: 頂起銀花雲月 | F3: 懸孔雀羽 | G3: 銀 | H3: 起=몸을 일으키다 · 銀=은 · 雲=구름 · 月=달 | I3: 정수리에 은화와 구름·달 장식을 세우고 | J3: 전립 꼭대기에 은꽃과 구름·달 모양 장식을 세우고 | K3: Y | L3: SD-1 자연·물질 | M3: TD-7 경물·감각 | N3: 銀花雲月 | O3: 투구 장식의 형상 | P3: 꽃과 구름·달의 형상이 투구 장식의 이름으로 옮겨감 | Q3: 낮음
A4: 3 | B4: 7 | C4: 12 | D4: 頂起銀花雲月 | E4: 懸孔雀羽 | F4: 腰繫藍方紗紬纏帶 | I4: 공작 깃을 매달았다 | J4: 공작 깃을 늘어뜨렸다 | K4: N | Q4: 보통
A5: 4 | B5: 8 | C5: 38 | D5: 者 | E5: 自檢其囊中得廿六文 | F5: 而東錢有禁 | H5: 自=스스로 · 其=그 · 中=가운데 · 得=얻다 · 六=여섯 · 文=무늬·글 | I5: 스스로 그 주머니 속을 헤아리니 스물여섯 문을 얻었다 | J5: 주머니를 뒤져 보니 스물여섯 푼이 있었다 | K5: N | Q5: 보통
A6: 5 | B6: 8 | C6: 39 | D6: 自檢其囊中得廿六文 | E6: 而東錢有禁 | F6: 不可出境 | G6: 錢 | H6: 而=말 잇는 조사 · 東=동쪽 · 錢=엽전 · 有=있다 | I6: 그런데 조선 돈은 금령이 있어 | J6: 그런데 우리 돈은 반출이 금지되어 | K6: N | Q6: 보통
A7: 6 | B7: 8 | C7: 40 | D7: 而東錢有禁 | E7: 不可出境 | F7: 棄之道則可惜 | H7: 不=아니다 · 可=옳다·가하다 · 出=나가다 | I7: 국경을 나갈 수 없다 | J7: 국경 밖으로 가져갈 수 없다 | K7: N | Q7: 보통
A8: 7 | B8: 8 | C8: 56 | D8: 滿酌一盞 | E8: 酹第一柱 | F8: 自祈利涉 | H8: 一=하나 | I8: 첫째 기둥에 술을 붓고 | J8: 첫째 기둥에 술을 부으며 | K8: N | Q8: 보통
A9: 8 | B9: 8 | C9: 57 | D9: 酹第一柱 | E9: 自祈利涉 | F9: 又斟一杯 | G9: 利 | H9: 自=스스로 · 利=날이 날카롭다 → 이롭다 | I9: 스스로 무사히 건너기를 빌었다 | J9: 무사히 건너게 해 달라고 빌었다 | K9: N | Q9: 보통
A10: 9 | B10: 8 | C10: 58 | D10: 自祈利涉 | E10: 又斟一杯 | F10: 酹第二柱 | H10: 又=또 · 一=하나 | I10: 또 한 잔을 따라 | J10: 다시 한 잔을 따라 | K10: N | Q10: 보통
A11: 10 | B11: 9 | C11: 9 | D11: 紅粉樓中別莫愁 | E11: 秋風數騎出邊頭 | F11: 畵船簫鼓無消息 | H11: 秋=가을 · 風=바람 · 數=세다·수 · 出=나가다 · 邊=가장자리 · 頭=머리 | I11: 가을바람에 두어 기마가 변방 어귀를 나서고 | J11: 가을바람에 몇 기마가 변방을 나서는데 | K11: N | Q11: 보통
A12: 11 | B12: 9 | C12: 10 | D12: 秋風數騎出邊頭 | E12: 畵船簫鼓無消息 | F12: 斷膓淸南第一州 | G12: 息 | H12: 無=없다 · 消=녹아 없어지다 · 息=숨쉬다 | I12: 그림배의 퉁소와 북은 소식이 없다 | J12: 그림배의 풍악 소리는 간 데 없고 | K12: N | Q12: 보통
A13: 12 | B13: 9 | C13: 11 | D13: 畵船簫鼓無消息 | E13: 斷膓淸南第一州 | F13: 此柳惠風入瀋陽時作也 | H13: 膓=창자 · 淸=맑다 · 南=남쪽 · 一=하나 · 州=고을 | I13: 청남 제일주에서 애를 끊는다 | J13: 청남 제일의 고을에서 애간장이 끊어진다 | K13: Y | L13: SD-2 신체·감각 | M13: TD-7 경물·감각 | N13: 斷膓 | O13: 이별의 슬픔 | P13: 창자가 끊어짐이 이별의 슬픔으로 옮겨감 | Q13: 높음
A14: 13 | B14: 10 | C14: 22 | D14: 舊件新浣 | E14: 鬅騰郭索 | F14: 可謂太崇儉矣 | I14: 머리는 헝클어지고 걸음은 게걸음이니 | J14: 머리는 헝클어지고 걸음은 게처럼 어정거리니 | K14: N | Q14: 보통
A15: 14 | B15: 10 | C15: 23 | D15: 鬅騰郭索 | E15: 可謂太崇儉矣 | F15: 稍俟副使之出城 | G15: 儉 | H15: 可=옳다·가하다 · 謂=이르다 · 儉=검소하다 · 矣=마치는 조사 | I15: 너무 검소함을 숭상한다 할 만하다 | J15: 지나치게 검소하다 할 만하다 | K15: Y | L15: SD-3 공간·방위 | M15: TD-4 도덕·책무 | N15: 崇 | O15: 숭상 | P15: 공간의 높음이 가치의 존숭으로 옮겨감 | Q15: 보통
A16: 15 | B16: 10 | C16: 24 | D16: 可謂太崇儉矣 | E16: 稍俟副使之出城 | F16: 乃按轡徐行 | H16: 使=시키다 · 之=가다 (조사로도 쓰임) · 出=나가다 · 城=성 | I16: 부사가 성을 나서기를 조금 기다려 | J16: 부사가 성을 나오기를 잠시 기다렸다가 | K16: N | Q16: 보통
A17: 16 | B17: 10 | C17: 37 | D17: 搜其禁物 | E17: 大者如黃金眞珠人參貂皮 | F17: 及包外濫銀 | H17: 大=크다 · 者=~하는 것·사람 · 如=같다 · 金=쇠붙이 · 眞=참되다 · 珠=구슬 · 人=사람 | I17: 큰 것은 황금·진주·인삼·담비 가죽 같은 것이고 | J17: 큰 것으로는 황금·진주·인삼·담비 가죽이 있고 | K17: N | Q17: 보통
A18: 17 | B18: 10 | C18: 38 | D18: 大者如黃金眞珠人參貂皮 | E18: 及包外濫銀 | F18: 小者新舊名目 | G18: 銀 | H18: 及=미치다 · 外=바깥 · 銀=은 | I18: 그리고 포 밖의 넘치는 은이며 | J18: 정해진 몫을 넘긴 은이 있으며 | K18: Y | L18: SD-1 자연·물질 | M18: TD-1 축적·유통 | N18: 濫 | O18: 한도 초과 | P18: 물이 넘침이 규정 초과의 은으로 옮겨감 | Q18: 보통
A19: 18 | B19: 10 | C19: 39 | D19: 及包外濫銀 | E19: 小者新舊名目 | F19: 不下數十種 | H19: 小=작다 · 者=~하는 것·사람 · 新=새롭다 · 舊=옛 · 名=이름 · 目=눈 | I19: 작은 것은 새롭고 오래된 여러 명목으로 | J19: 작은 것은 이런저런 명목이 붙어 | K19: N | Q19: 보통
A20: 19 | B20: 10 | C20: 54 | D20: 而其實 | E20: 文具而已 | F20: 灣賈之先期潛越 | H20: 文=무늬·글 · 而=말 잇는 조사 · 已=이미 | I20: 문서상의 격식일 뿐이다 | J20: 문서상의 형식에 지나지 않는다 | K20: N | Q20: 보통
A21: 20 | B21: 10 | C21: 55 | D21: 文具而已 | E21: 灣賈之先期潛越 | F21: 有誰禁之 | G21: 賈 | H21: 賈=장사하다 · 之=가다 (조사로도 쓰임) · 先=먼저 · 潛=물속에 잠기다 | I21: 의주 상인이 기일에 앞서 몰래 건너는 것을 | J21: 의주 상인이 미리 몰래 국경을 넘는 것을 | K21: Y | L21: SD-1 자연·물질 | M21: TD-1 축적·유통 | N21: 潛越 | O21: 밀무역 | P21: 물속에 잠김이 몰래 국경을 넘음으로 옮겨감 | Q21: 보통
A22: 21 | B22: 10 | C22: 56 | D22: 灣賈之先期潛越 | E22: 有誰禁之 | F22: 禁物之現捉於初旗者 | H22: 有=있다 · 之=가다 (조사로도 쓰임) | I22: 누가 금하겠는가 | J22: 누가 막을 수 있겠는가 | K22: N | Q22: 보통
A23: 22 | B23: 10 | C23: 66 | D23: 今行原包猶未及半 | E23: 多空包者 | F23: 其濫銀奚論 | H23: 多=많다 · 者=~하는 것·사람 | I23: 빈 포가 많은 자이니 | J23: 빈 짐짝이 많으니 | K23: N | Q23: 보통
A24: 23 | B24: 10 | C24: 67 | D24: 多空包者 | E24: 其濫銀奚論 | G24: 銀 | H24: 其=그 · 銀=은 | I24: 그 넘치는 은을 어찌 논하겠는가 | J24: 규정을 넘긴 은을 따질 것이 있겠는가 | K24: Y | L24: SD-1 자연·물질 | M24: TD-1 축적·유통 | N24: 濫 | O24: 한도 초과 | P24: 물이 넘침이 규정 초과의 은으로 옮겨감 | Q24: 보통
A25: 24 | B25: 11 | C25: 1 | E25: 茶啖草草 | F25: 乍進旋退 | H25: 茶=차 | I25: 차와 다과가 변변찮아 | J25: 차와 다과가 변변찮아 | K25: N | Q25: 보통
A26: 25 | B26: 11 | C26: 64 | D26: 惟 | E26: 知道者能之 | F26: 鄭之子產 | H26: 知=알다 · 道=길 · 者=~하는 것·사람 · 能=능하다 · 之=가다 (조사로도 쓰임) | I26: 도를 아는 자라야 능하다 | J26: 도를 아는 자라야 할 수 있는 일이다 | K26: N | Q26: 보통
A27: 26 | B27: 11 | C27: 65 | D27: 知道者能之 | E27: 鄭之子產 | G27: 產 | H27: 之=가다 (조사로도 쓰임) · 子=아들 | I27: 정나라의 자산이다 | J27: 정나라 자산이 그런 사람이다 | K27: N | Q27: 보통
A28: 27 | B28: 12 | C28: 1 | E28: 船已泊岸 | F28: 蘆荻如織 | H28: 已=이미 | I28: 배가 이미 언덕에 닿았다 | J28: 배가 벌써 기슭에 닿았다 | K28: N | Q28: 보통
A29: 28 | B29: 12 | C29: 36 | D29: 有一人起立應聲曰 | E29: 爾們的不時節 | F29: 緣何朝貢入大國 | H29: 的=~의 (백화) · 不=아니다 · 時=때 · 節=대나무의 마디 | I29: 너희들은 철이 아닌데 | J29: 너희들은 철도 아닌데 | K29: N | Q29: 보통
A30: 29 | B30: 12 | C30: 37 | D30: 爾們的不時節 | E30: 緣何朝貢入大國 | F30: 暑天裏長途 | G30: 貢 | H30: 何=무엇 · 朝=아침·조정 · 貢=바치는 물건 · 入=들다 · 大=크다 · 國=나라 | I30: 무슨 까닭에 조공으로 대국에 들어오는가 | J30: 무슨 일로 조공하러 대국에 들어오는가 | K30: N | Q30: 보통
A31: 30 | B31: 12 | C31: 38 | D31: 緣何朝貢入大國 | E31: 暑天裏長途 | F31: 辛苦時大 | H31: 天=하늘 · 長=길다·자라다 | I31: 더운 날에 먼 길을 | J31: 이 더위에 먼 길을 | K31: N | Q31: 보통
A32: 31 | B32: 12 | C32: 133 | D32: 余騰身載其背 | E32: 其人笑嘻嘻入船 | F32: 出氣長息曰 | H32: 其=그 · 人=사람 · 笑=웃다 · 入=들다 | I32: 그 사람이 싱글싱글 웃으며 배에 들어와 | J32: 그 사람이 히죽히죽 웃으며 배에 올라 | K32: N | Q32: 보통
A33: 32 | B33: 12 | C33: 134 | D33: 其人笑嘻嘻入船 | E33: 出氣長息曰 | F33: 黑旋風媽媽這樣沉挑時 | G33: 息 | H33: 出=나가다 · 氣=기운 · 長=길다·자라다 · 息=숨쉬다 · 曰=말하다 | I33: 숨을 내쉬고 길게 한숨지으며 말했다 | J33: 숨을 몰아쉬고 길게 한숨을 내쉬며 말했다 | K33: N | Q33: 보통
A34: 33 | B34: 12 | C34: 135 | D34: 出氣長息曰 | E34: 黑旋風媽媽這樣沉挑時 | F34: 巴不得上了沂 | H34: 風=바람 · 時=때 | I34: 흑선풍 어미가 이렇게 무겁게 멜 때 | J34: 흑선풍의 어미를 이렇게 무겁게 멜 적에 | K34: N | Q34: 보통
A35: 34 | B35: 13 | C35: 46 | D35: 或五人同帳 | E35: 譯卒及刷馬驅人 | F35: 伍伍什什 | H35: 譯=통역하다 · 及=미치다 · 馬=말 · 人=사람 | I35: 역졸과 쇄마 몰이꾼들이 | J35: 역졸과 말몰이꾼들이 | K35: N | Q35: 보통
A36: 35 | B36: 13 | C36: 47 | D36: 譯卒及刷馬驅人 | E36: 伍伍什什 | F36: 靠溪搆木 | G36: 什 | H36: 什=열 | I36: 다섯씩 열씩 짝지어 | J36: 다섯씩 열씩 무리를 지어 | K36: N | Q36: 보통
A37: 36 | B37: 13 | C37: 48 | D37: 伍伍什什 | E37: 靠溪搆木 | F37: 炊烟相連 | I37: 시내에 기대어 나무를 얽고 | J37: 시냇가에 나무를 얽어 얽매고 | K37: N | Q37: 보통
A38: 37 | B38: 13 | C38: 52 | D38: 儼 | E38: 成村閭 | F38: 灣商一隊 | H38: 成=이루다 | I38: 마을을 이루었다 | J38: 한 마을을 이루었다 | K38: N | Q38: 보통
A39: 38 | B39: 13 | C39: 53 | D39: 成村閭 | E39: 灣商一隊 | F39: 自爲一屯 | G39: 商 | H39: 商=장사하다 · 一=하나 | I39: 의주 상인 한 무리는 | J39: 의주 상인 한 패는 | K39: N | Q39: 보통
A40: 39 | B40: 13 | C40: 54 | D40: 灣商一隊 | E40: 自爲一屯 | F40: 臨溪洗數十鷄 | H40: 自=스스로 · 爲=하다·되다 · 一=하나 | I40: 스스로 한 둔을 이루어 | J40: 따로 한 무리를 지어 | K40: N | Q40: 보통
...

Sheet 성경잡지
A1: 연번 | B1: 문단 | C1: 절번호 | D1: 앞 문맥(참고) | E1: ★ 판정 대상 절 ★ | F1: 뒤 문맥(참고) | G1: 트리거 | H1: 주요 글자의 기본 의미 | I1: 은유 여부 | J1: 원천 영역 | K1: 목표 영역 | L1: 원천 어휘 | M1: 목표 개념 | N1: 판정 근거 | O1: 확신도 | P1: 비고
A2: 1 | B2: 8 | C2: 59 | D2: 少焉主人之小孫 | E2: 手提吶叭 | F2: 氣息喘喘 | H2: 手=손 | I2: N | O2: 보통
A3: 2 | B3: 8 | C3: 60 | D3: 手提吶叭 | E3: 氣息喘喘 | F3: 走入堂裏 | G3: 息 | H3: 氣=기운 · 息=숨쉬다 · 喘=헐떡이다 | I3: N | O3: 보통
A4: 3 | B4: 8 | C4: 61 | D4: 氣息喘喘 | E4: 走入堂裏 | F4: 抱老公項 | H4: 入=들다 | I4: N | O4: 보통
A5: 4 | B5: 8 | C5: 62 | D5: 走入堂裏 | E5: 抱老公項 | F5: 要買吶叭 | H5: 老=늙다 · 公=공변되다·귀인 | I5: N | O5: 보통
A6: 5 | B6: 8 | C6: 63 | D6: 抱老公項 | E6: 要買吶叭 | F6: 老公慈意滿面曰 | G6: 買 | H6: 要=구하다 · 買=사다 | I6: N | O6: 보통
A7: 6 | B7: 8 | C7: 64 | D7: 要買吶叭 | E7: 老公慈意滿面曰 | F7: 這箇不中用 | H7: 老=늙다 · 公=공변되다·귀인 · 面=얼굴 · 曰=말하다 | I7: N | O7: 보통
A8: 7 | B8: 8 | C8: 82 | D8: 余亦責軍牢索去好矣 | E8: 何必若是無聊人 | F8: 余問這狗子那地所產 | H8: 何=무엇 · 必=반드시 · 若=같다 · 是=옳다·이것 · 無=없다 · 人=사람 | I8: N | O8: 보통
A9: 8 | B9: 8 | C9: 83 | D9: 何必若是無聊人 | E9: 余問這狗子那地所產 | F9: 主人 | G9: 產 | H9: 余=나 · 問=묻다 · 子=아들 · 地=땅 · 所=바·곳 | I9: N | O9: 보통
A10: 9 | B10: 8 | C10: 84 | D10: 余問這狗子那地所產 | E10: 主人 | F10: 答曰 | H10: 主=주인 · 人=사람 | I10: N | O10: 보통
A11: 10 | B11: 8 | C11: 85 | D11: 主人 | E11: 答曰 | F11: 雲南所產 | H11: 答=대답하다 · 曰=말하다 | I11: N | O11: 보통
A12: 11 | B12: 8 | C12: 86 | D12: 答曰 | E12: 雲南所產 | F12: 蜀中亦有這樣的小狗 | G12: 產 | H12: 雲=구름 · 南=남쪽 · 所=바·곳 | I12: N | O12: 보통
A13: 12 | B13: 8 | C13: 87 | D13: 雲南所產 | E13: 蜀中亦有這樣的小狗 | F13: 此名玉兎兒 | H13: 中=가운데 · 亦=또한 · 有=있다 · 的=~의 (백화) · 小=작다 | I13: N | O13: 보통
A14: 13 | B14: 8 | C14: 89 | D14: 此名玉兎兒 | E14: 那箇叫做雪獅子 | F14: 幷是雲南產 | H14: 做=하다 (백화) · 子=아들 | I14: N | O14: 보통
A15: 14 | B15: 8 | C15: 90 | D15: 那箇叫做雪獅子 | E15: 幷是雲南產 | F15: 主人叫玉兎兒 | G15: 產 | H15: 是=옳다·이것 · 雲=구름 · 南=남쪽 | I15: N | O15: 보통
A16: 15 | B16: 8 | C16: 91 | D16: 幷是雲南產 | E16: 主人叫玉兎兒 | F16: 叩頭 | H16: 主=주인 · 人=사람 · 玉=옥 | I16: N | O16: 보통
A17: 16 | B17: 8 | C17: 100 | D17: 客官旣然愛玩此 | E17: 微物時 | F17: 情願拜送準貢回還時 | H17: 物=물건 · 時=때 | I17: N | O17: 보통
A18: 17 | B18: 8 | C18: 101 | D18: 微物時 | E18: 情願拜送準貢回還時 | F18: 客官不妨携去 | G18: 貢 | H18: 送=보내다 · 貢=바치는 물건 · 還=돌아오다 · 時=때 | I18: N | O18: 보통
A19: 18 | B19: 8 | C19: 102 | D19: 情願拜送準貢回還時 | E19: 客官不妨携去 | F19: 余答曰 | H19: 客=손님 · 官=벼슬 · 不=아니다 · 去=가다 | I19: N | O19: 보통
A20: 19 | B20: 8 | C20: 113 | D20: 遂給張福與昌大共食 | E20: 自入舖子裏 | F20: 買喫一椀麵 | H20: 自=스스로 · 入=들다 · 舖=가게 · 子=아들 | I20: N | O20: 보통
A21: 20 | B21: 8 | C21: 114 | D21: 自入舖子裏 | E21: 買喫一椀麵 | F21: 一 | G21: 買 | H21: 買=사다 · 一=하나 | I21: N | O21: 보통
A22: 21 | B22: 8 | C22: 115 | D22: 買喫一椀麵 | E22: 一 | F22: 觶燒酒 | H22: 一=하나 | I22: N | O22: 보통
A23: 22 | B23: 9 | C23: 15 | D23: 車馬雲屯 | E23: 促鞭行下馬少憩 | F23: 客商數百人 | H23: 行=걸어가다 · 下=아래쪽 · 馬=말 · 少=적다 | I23: N | O23: 보통
A24: 23 | B24: 9 | C24: 16 | D24: 促鞭行下馬少憩 | E24: 客商數百人 | F24: 卸擔納凉 | G24: 商 | H24: 客=손님 · 商=장사하다 · 數=세다·수 · 百=일백 · 人=사람 | I24: N | O24: 보통
A25: 24 | B25: 9 | C25: 17 | D25: 客商數百人 | E25: 卸擔納凉 | F25: 或踞柳根 | I25: N | O25: 보통
A26: 25 | B26: 9 | C26: 36 | D26: 車三十餘乘 | E26: 皆滿載石煤 | F26: 賣酒賣茶 | H26: 皆=모두 | I26: N | O26: 보통
A27: 26 | B27: 9 | C27: 37 | D27: 皆滿載石煤 | E27: 賣酒賣茶 | F27: 賣餠果 | G27: 賣 | H27: 賣=팔다 · 酒=술 · 茶=차 | I27: N | O27: 보통
A28: 27 | B28: 9 | C28: 38 | D28: 賣酒賣茶 | E28: 賣餠果 | F28: 諸般飮食者 | G28: 賣 | H28: 賣=팔다 | I28: N | O28: 보통
A29: 28 | B29: 9 | C29: 39 | D29: 賣餠果 | E29: 諸般飮食者 | F29: 皆聚柳陰下 | H29: 諸=여러 · 飮=마시다 · 食=먹다 · 者=~하는 것·사람 | I29: N | O29: 보통
A30: 29 | B30: 10 | C30: 1 | E30: 渾河 | F30: 一名阿利江 | I30: N | O30: 보통
A31: 30 | B31: 10 | C31: 2 | D31: 渾河 | E31: 一名阿利江 | F31: 一名小遼水 | G31: 利 | H31: 一=하나 · 名=이름 · 利=날이 날카롭다 → 이롭다 · 江=큰 강 | I31: N | O31: 보통
A32: 31 | B32: 10 | C32: 3 | D32: 一名阿利江 | E32: 一名小遼水 | F32: 源出長白山 | H32: 一=하나 · 名=이름 · 小=작다 · 水=물 | I32: N | O32: 보통
A33: 32 | B33: 11 | C33: 15 | D33: 郭內民物之繁華 | E33: 市肆之侈盛 | F33: 十倍遼陽 | H33: 市=저자 · 之=가다 (조사로도 쓰임) | I33: N | O33: 보통
A34: 33 | B34: 11 | C34: 16 | D34: 市肆之侈盛 | E34: 十倍遼陽 | F34: 矣 | G34: 倍 | H34: 十=열 · 倍=갑절 · 陽=볕 | I34: Y | J34: (수사 기제) | K34: TD-1 축적·유통 | L34: 十倍 | M34: 과장 | N34: 배수 표현으로 시장 규모를 부풀림 | O34: 보통
A35: 34 | B35: 11 | C35: 17 | D35: 十倍遼陽 | E35: 矣 | F35: 入關廟少憩 | H35: 矣=마치는 조사 | I35: N | O35: 보통
A36: 35 | B36: 11 | C36: 32 | D36: 身披一領野繭紗道袍 | E36: 項戴藤笠 | F36: 足穿貢緞黑靴 | I36: N | O36: 보통
A37: 36 | B37: 11 | C37: 33 | D37: 項戴藤笠 | E37: 足穿貢緞黑靴 | F37: 脫笠自撫其髻曰 | G37: 貢 | H37: 足=발 · 貢=바치는 물건 | I37: N | O37: 보통
A38: 37 | B38: 11 | C38: 34 | D38: 足穿貢緞黑靴 | E38: 脫笠自撫其髻曰 | F38: 與相公一樣 | H38: 自=스스로 · 其=그 · 曰=말하다 | I38: N | O38: 보통
A39: 38 | B39: 12 | C39: 17 | D39: 彩閣雕牕 | E39: 金扁碧榜 | F39: 貨寶 | H39: 金=쇠붙이 | I39: N | O39: 보통
A40: 39 | B40: 12 | C40: 18 | D40: 金扁碧榜 | E40: 貨寶 | F40: 財賄 | G40: 貨 | H40: 貨=사고파는 물건 | I40: N | O40: 보통
...

Sheet 일신수필
A1: 연번 | B1: 문단 | C1: 절번호 | D1: 앞 문맥(참고) | E1: ★ 판정 대상 절 ★ | F1: 뒤 문맥(참고) | G1: 트리거 | H1: 주요 글자의 기본 의미 | I1: 은유 여부 | J1: 원천 영역 | K1: 목표 영역 | L1: 원천 어휘 | M1: 목표 개념 | N1: 판정 근거 | O1: 확신도 | P1: 비고
A2: 1 | B2: 3 | C2: 20 | D2: 吾今疾書至此 | E2: 而一墨之頃 | F2: 不過瞬息 | H2: 而=말 잇는 조사 · 一=하나 · 之=가다 (조사로도 쓰임) | I2: N | O2: 보통
A3: 2 | B3: 3 | C3: 21 | D3: 而一墨之頃 | E3: 不過瞬息 | F3: 一瞬一息之頃 | G3: 息 | H3: 不=아니다 · 過=지나다 · 瞬=눈을 깜빡이다 · 息=숨쉬다 | I3: Y | J3: SD-2 신체·감각 | K3: TD-7 경물·감각 | L3: 瞬息 | M3: 시간의 체감 | N3: 눈 깜빡임과 숨이 시간의 단위로 옮겨감 | O3: 높음
A4: 3 | B4: 3 | C4: 22 | D4: 不過瞬息 | E4: 一瞬一息之頃 | F4: 奄成小古小今 | G4: 息 | H4: 一=하나 · 瞬=눈을 깜빡이다 · 息=숨쉬다 · 之=가다 (조사로도 쓰임) | I4: Y | J4: SD-2 신체·감각 | K4: TD-7 경물·감각 | L4: 一瞬一息 | M4: 시간의 체감 | N4: 눈 깜빡임과 숨이 시간의 단위로 옮겨감 | O4: 높음
A5: 4 | B5: 3 | C5: 23 | D5: 一瞬一息之頃 | E5: 奄成小古小今 | F5: 則一古一今 | H5: 成=이루다 · 小=작다 · 古=옛 · 今=이제 | I5: N | O5: 보통
A6: 5 | B6: 3 | C6: 25 | D6: 則一古一今 | E6: 亦可謂大瞬 | F6: 大息矣 | H6: 亦=또한 · 可=옳다·가하다 · 謂=이르다 · 大=크다 · 瞬=눈을 깜빡이다 | I6: Y | J6: SD-2 신체·감각 | K6: TD-7 경물·감각 | L6: 大瞬 | M6: 시간의 체감 | N6: 눈 깜빡임이 확대되어 큰 시간 단위로 옮겨감 | O6: 보통
A7: 6 | B7: 3 | C7: 26 | D7: 亦可謂大瞬 | E7: 大息矣 | F7: 乃欲立名立事於其間 | G7: 息 | H7: 大=크다 · 息=숨쉬다 · 矣=마치는 조사 | I7: N | O7: 보통
A8: 7 | B8: 3 | C8: 27 | D8: 大息矣 | E8: 乃欲立名立事於其間 | F8: 豈不哀哉 | H8: 乃=이에 · 欲=하고자 하다 · 立=서다 · 名=이름 · 事=일 · 於=~에 · 其=그 | I8: N | O8: 보통
A9: 8 | B9: 3 | C9: 35 | D9: 霧漫漫 | E9: 上承月光 | F9: 如水銀海 | H9: 上=위쪽 · 月=달 · 光=빛 | I9: N | O9: 보통
A10: 9 | B10: 3 | C10: 36 | D10: 上承月光 | E10: 如水銀海 | F10: 海底殷殷有聲如鼾鼻 | G10: 銀 | H10: 如=같다 · 水=물 · 銀=은 · 海=바다 | I10: Y | J10: SD-1 자연·물질 | K10: TD-7 경물·감각 | L10: 如水銀海 | M10: 달빛 어린 물결 | N10: 수은의 바다가 달빛 어린 물결로 옮겨감(직유) | O10: 높음
A11: 10 | B11: 3 | C11: 37 | D11: 如水銀海 | E11: 海底殷殷有聲如鼾鼻 | F11: 寺僧相語曰 | H11: 海=바다 · 有=있다 · 聲=소리 · 如=같다 | I11: Y | J11: SD-2 신체·감각 | K11: TD-7 경물·감각 | L11: 如鼾鼻 | M11: 물소리 | N11: 코 고는 소리가 물소리로 옮겨감(직유) | O11: 높음
A12: 11 | B12: 4 | C12: 60 | D12: 士庶人也薙髮 | E12: 雖功德侔殷周 | F12: 富强邁秦漢 | H12: 雖=비록 · 德=덕 · 周=두루 | I12: N | O12: 보통
A13: 12 | B13: 4 | C13: 61 | D13: 雖功德侔殷周 | E13: 富强邁秦漢 | F13: 自生民以來 | G13: 富 | H13: 富=재물이 넉넉하다 · 强=굳세다 · 邁=멀리 나아가다 · 漢=한나라·사내 | I13: Y | J13: SD-5 운동·시간 | K13: TD-2 권력·지배 | L13: 邁 | M13: 능가 | N13: 앞질러 감이 국력의 우월로 옮겨감 | O13: 보통
A14: 13 | B14: 4 | C14: 62 | D14: 富强邁秦漢 | E14: 自生民以來 | F14: 未有薙髮之天子也 | H14: 自=스스로 · 生=낳다·살다 · 民=백성 · 以=~로써 · 來=오다 | I14: N | O14: 보통
A15: 14 | B15: 4 | C15: 136 | D15: 固自 | E15: 在也 | F15: 正德利用厚生之具 | H15: 在=있다 · 也=단정하는 조사 | I15: N | O15: 보통
A16: 15 | B16: 4 | C16: 137 | D16: 在也 | E16: 正德利用厚生之具 | F16: 固自如也 | G16: 利 | H16: 正=바르다 · 德=덕 · 利=날이 날카롭다 → 이롭다 · 用=쓰다 · 厚=두껍다 · 生=낳다·살다 · 之=가다 (조사로도 쓰임) | I16: N | O16: 보통
A17: 16 | B17: 4 | C17: 138 | D17: 正德利用厚生之具 | E17: 固自如也 | F17: 崔盧王謝之氏族固不廢也 | H17: 自=스스로 · 如=같다 · 也=단정하는 조사 | I17: N | O17: 보통
A18: 17 | B18: 4 | C18: 145 | D18: 固不變也 | E18: 彼胡虜者 | F18: 誠知中國之可利 | H18: 彼=저 · 者=~하는 것·사람 | I18: N | O18: 보통
A19: 18 | B19: 4 | C19: 146 | D19: 彼胡虜者 | E19: 誠知中國之可利 | F19: 而足以久享 | G19: 利 | H19: 知=알다 · 中=가운데 · 國=나라 · 之=가다 (조사로도 쓰임) · 可=옳다·가하다 · 利=날이 날카롭다 → 이롭다 | I19: N | O19: 보통
A20: 19 | B20: 4 | C20: 147 | D20: 誠知中國之可利 | E20: 而足以久享 | F20: 則至於奪而據 | H20: 而=말 잇는 조사 · 足=발 · 以=~로써 · 久=오래되다 | I20: N | O20: 보통
A21: 20 | B21: 4 | C21: 151 | D21: 若固有之 | E21: 爲天下者 | F21: 苟利於民而厚於國 | H21: 爲=하다·되다 · 天=하늘 · 下=아래쪽 · 者=~하는 것·사람 | I21: N | O21: 보통
A22: 21 | B22: 4 | C22: 152 | D22: 爲天下者 | E22: 苟利於民而厚於國 | F22: 雖其法之或出於夷狄 | G22: 利 | H22: 利=날이 날카롭다 → 이롭다 · 於=~에 · 民=백성 · 而=말 잇는 조사 · 厚=두껍다 · 國=나라 | I22: Y | J22: SD-3 공간·방위 | K22: TD-2 권력·지배 | L22: 厚於國 | M22: 국익 | N22: 두께가 나라의 이로움으로 옮겨감 | O22: 보통
A23: 22 | B23: 4 | C23: 153 | D23: 苟利於民而厚於國 | E23: 雖其法之或出於夷狄 | F23: 固將取而則之 | H23: 雖=비록 · 其=그 · 法=법 · 之=가다 (조사로도 쓰임) · 或=혹 · 出=나가다 · 於=~에 | I23: N | O23: 보통
A24: 23 | B24: 4 | C24: 166 | D24: 自耕蠶陶冶 | E24: 以至通 | F24: 工惠商 | H24: 以=~로써 · 至=이르다 · 通=통하다 | I24: N | O24: 보통
A25: 24 | B25: 4 | C25: 167 | D25: 以至通 | E25: 工惠商 | F25: 莫不學焉 | G25: 商 | H25: 工=장인 · 商=장사하다 | I25: N | O25: 보통
A26: 25 | B26: 4 | C26: 168 | D26: 工惠商 | E26: 莫不學焉 | F26: 人十己百 | H26: 莫=없다 · 不=아니다 · 學=배우다 · 焉=어찌 | I26: N | O26: 보통
A27: 26 | B27: 4 | C27: 169 | D27: 莫不學焉 | E27: 人十己百 | F27: 先利吾民 | H27: 人=사람 · 十=열 · 百=일백 | I27: N | O27: 보통
A28: 27 | B28: 4 | C28: 170 | D28: 人十己百 | E28: 先利吾民 | F28: 使吾民制梃 | G28: 利 | H28: 先=먼저 · 利=날이 날카롭다 → 이롭다 · 吾=나 · 民=백성 | I28: N | O28: 보통
A29: 28 | B29: 4 | C29: 171 | D29: 先利吾民 | E29: 使吾民制梃 | F29: 而足以撻彼之堅甲利兵 | H29: 使=시키다 · 吾=나 · 民=백성 · 制=만들다·제도 | I29: N | O29: 보통
A30: 29 | B30: 4 | C30: 172 | D30: 使吾民制梃 | E30: 而足以撻彼之堅甲利兵 | F30: 然後謂中國無可觀可 | G30: 利 | H30: 而=말 잇는 조사 · 足=발 · 以=~로써 · 彼=저 · 之=가다 (조사로도 쓰임) · 利=날이 날카롭다 → 이롭다 · 兵=무기 | I30: N | O30: 보통
A31: 30 | B31: 4 | C31: 173 | D31: 而足以撻彼之堅甲利兵 | E31: 然後謂中國無可觀可 | F31: 也 | H31: 然=그러하다 · 後=뒤 · 謂=이르다 · 中=가운데 · 國=나라 · 無=없다 · 可=옳다·가하다 | I31: N | O31: 보통
A32: 31 | B32: 4 | C32: 184 | D32: 爲波濤之紋 | E32: 四合而成連環之形 | F32: 四背而成古魯錢 | H32: 四=넷 · 而=말 잇는 조사 · 成=이루다 · 連=잇다 · 之=가다 (조사로도 쓰임) · 形=모양 | I32: N | O32: 보통
A33: 32 | B33: 4 | C33: 185 | D33: 四合而成連環之形 | E33: 四背而成古魯錢 | F33: 嵌空玲瓏 | G33: 錢 | H33: 四=넷 · 而=말 잇는 조사 · 成=이루다 · 古=옛 · 錢=엽전 | I33: N | O33: 보통
A34: 33 | B34: 4 | C34: 186 | D34: 四背而成古魯錢 | E34: 嵌空玲瓏 | F34: 外內交映 | I34: N | O34: 보통
A35: 34 | B35: 4 | C35: 191 | D35: 之文章斯在矣 | E35: 民家門庭 | F35: 貧不能鋪甎 | H35: 民=백성 · 家=집 · 門=문 | I35: N | O35: 보통
A36: 35 | B36: 4 | C36: 192 | D36: 民家門庭 | E36: 貧不能鋪甎 | F36: 則聚諸色琉璃碎瓦及水邊小礫之磨圓者 | G36: 貧 | H36: 貧=재물이 모자라다 · 不=아니다 · 能=능하다 | I36: N | O36: 보통
A37: 36 | B37: 4 | C37: 193 | D37: 貧不能鋪甎 | E37: 則聚諸色琉璃碎瓦及水邊小礫之磨圓者 | F37: 錯成花樹鳥獸之形 | H37: 則=곧 · 諸=여러 · 色=빛깔 · 瓦=기와 · 及=미치다 · 水=물 · 邊=가장자리 · 小=작다 · 之=가다 (조사로도 쓰임) · 者=~하는 것·사람 | I37: N | O37: 보통
A38: 37 | B38: 6 | C38: 41 | D38: 舜封十有二山 | E38: 以醫巫閭爲幽州之鎭 | F38: 夏商周秦皆因之 | H38: 以=~로써 · 爲=하다·되다 · 州=고을 · 之=가다 (조사로도 쓰임) | I38: N | O38: 보통
A39: 38 | B39: 6 | C39: 42 | D39: 以醫巫閭爲幽州之鎭 | E39: 夏商周秦皆因之 | F39: 禮視嶽瀆 | G39: 商 | H39: 商=장사하다 · 周=두루 · 皆=모두 · 因=말미암다 · 之=가다 (조사로도 쓰임) | I39: N | O39: 보통
A40: 39 | B40: 6 | C40: 43 | D40: 夏商周秦皆因之 | E40: 禮視嶽瀆 | F40: 雖未知廟刱何代 | H40: 禮=예 | I40: N | O40: 보통
...

Sheet 관내정사
A1: 연번 | B1: 문단 | C1: 절번호 | D1: 앞 문맥(참고) | E1: ★ 판정 대상 절 ★ | F1: 뒤 문맥(참고) | G1: 트리거 | H1: 주요 글자의 기본 의미 | I1: 은유 여부 | J1: 원천 영역 | K1: 목표 영역 | L1: 원천 어휘 | M1: 목표 개념 | N1: 판정 근거 | O1: 확신도 | P1: 비고
A2: 1 | B2: 4 | C2: 114 | D2: 渭謂高麗紙 | E2: 不宜畵 | F2: 惟錢厚者稍佳 | H2: 不=아니다 | I2: N | O2: 보통
A3: 2 | B3: 4 | C3: 115 | D3: 不宜畵 | E3: 惟錢厚者稍佳 | F3: 其不見可 | G3: 錢 | H3: 錢=엽전 · 厚=두껍다 · 者=~하는 것·사람 | I3: N | O3: 보통
A4: 3 | B4: 4 | C4: 116 | D4: 惟錢厚者稍佳 | E4: 其不見可 | F4: 如此 | H4: 其=그 · 不=아니다 · 見=보다 · 可=옳다·가하다 | I4: N | O4: 보통
A5: 4 | B5: 4 | C5: 208 | D5: 余進至池邊 | E5: 暫倚欄干而立 | F5: 堂中寂然屛息 | H5: 而=말 잇는 조사 · 立=서다 | I5: N | O5: 보통
A6: 5 | B6: 4 | C6: 209 | D6: 暫倚欄干而立 | E6: 堂中寂然屛息 | F6: 隱暎從簾隙偸看 | G6: 息 | H6: 中=가운데 · 然=그러하다 · 屛=숨을 죽이다 · 息=숨쉬다 | I6: Y | J6: SD-2 신체·감각 | K6: TD-7 경물·감각 | L6: 屛息 | M6: 실내의 고요 | N6: 숨을 죽임이 실내의 고요로 옮겨감 | O6: 보통
A7: 6 | B7: 4 | C7: 210 | D7: 堂中寂然屛息 | E7: 隱暎從簾隙偸看 | F7: 余徘徊 | H7: 從=좇다 · 隙=틈 | I7: N | O7: 보통
A8: 7 | B8: 4 | C8: 314 | D8: 至昌黎諸濱海之縣 | E8: 山氣尤佳 | F8: 禹貢碣石 | H8: 山=산 · 氣=기운 | I8: N | O8: 보통
A9: 8 | B9: 4 | C9: 315 | D9: 山氣尤佳 | E9: 禹貢碣石 | F9: 近在縣西二十里 | G9: 貢 | H9: 貢=바치는 물건 | I9: N | O9: 보통
A10: 9 | B10: 4 | C10: 316 | D10: 禹貢碣石 | E10: 近在縣西二十里 | F10: 曹操詩 | H10: 在=있다 · 西=서쪽 · 二=둘 · 十=열 | I10: N | O10: 보통
A11: 10 | B11: 4 | C11: 353 | D11: 抱城逶迤 | E11: 地形甚似平壤 | F11: 而昭曠倍之 | H11: 地=땅 · 形=모양 · 平=평평하다 | I11: N | O11: 보통
A12: 11 | B12: 4 | C12: 354 | D12: 地形甚似平壤 | E12: 而昭曠倍之 | F12: 而但無大同淸江耳 | G12: 倍 | H12: 而=말 잇는 조사 · 倍=갑절 · 之=가다 (조사로도 쓰임) | I12: N | O12: 보통
A13: 12 | B13: 4 | C13: 355 | D13: 而昭曠倍之 | E13: 而但無大同淸江耳 | F13: 世傳金學士黃元登浮 | H13: 而=말 잇는 조사 · 無=없다 · 大=크다 · 同=같다 · 淸=맑다 · 江=큰 강 · 耳=귀 | I13: N | O13: 보통
A14: 13 | B14: 4 | C14: 389 | D14: 輔之地 | E14: 廬舍市舖 | F14: 繁富倍他 | H14: 市=저자 · 舖=가게 | I14: N | O14: 보통
A15: 14 | B15: 4 | C15: 390 | D15: 廬舍市舖 | E15: 繁富倍他 | F15: 進士牌額 | G15: 富 倍 | H15: 繁=초목이 우거지다 · 富=재물이 넉넉하다 · 倍=갑절 | I15: Y | J15: SD-1 자연·물질 | K15: TD-5 문명·제도 | L15: 繁富 | M15: 번성 | N15: 초목의 무성함이 마을의 융성으로 옮겨감 | O15: 보통
A16: 15 | B16: 4 | C16: 391 | D16: 繁富倍他 | E16: 進士牌額 | F16: 比撫寧尤盛 | H16: 進=나아가다 · 士=선비 | I16: N | O16: 보통
A17: 16 | B17: 4 | C17: 397 | D17: 偶入一宅 | E17: 方張燈 | F17: 刻高麗進貢圖 | H17: 方=모나다·바야흐로 | I17: N | O17: 보통
A18: 17 | B18: 4 | C18: 398 | D18: 方張燈 | E18: 刻高麗進貢圖 | F18: 沿路店壁 | G18: 貢 | H18: 高=높다 · 麗=곱다 · 進=나아가다 · 貢=바치는 물건 | I18: N | O18: 보통
A19: 18 | B19: 4 | C19: 399 | D19: 刻高麗進貢圖 | E19: 沿路店壁 | F19: 多貼此畵 | H19: 路=길 | I19: N | O19: 보통
A20: 19 | B20: 4 | C20: 435 | D20: 墨鱗成堆 | E20: 破敗荒陋 | F20: 不直一錢 | H20: 敗=싸움에 지다 · 荒=땅이 거칠어지다 | I20: N | O20: 보통
A21: 20 | B21: 4 | C21: 436 | D21: 破敗荒陋 | E21: 不直一錢 | F21: 第觀胡生擧措 | G21: 錢 | H21: 不=아니다 · 一=하나 · 錢=엽전 | I21: N | O21: 보통
A22: 21 | B22: 4 | C22: 437 | D22: 不直一錢 | E22: 第觀胡生擧措 | F22: 眞若絶世奇寶 | H22: 生=낳다·살다 | I22: N | O22: 보통
A23: 22 | B23: 4 | C23: 457 | D23: 曰 | E23: 晡刻貴國金相公 | F23: 來弊舖賣此 | H23: 貴=귀하다 · 國=나라 · 金=쇠붙이 · 相=서로 · 公=공변되다·귀인 | I23: N | O23: 보통
A24: 23 | B24: 4 | C24: 458 | D24: 晡刻貴國金相公 | E24: 來弊舖賣此 | F24: 金相公老實人 | G24: 賣 | H24: 來=오다 · 舖=가게 · 賣=팔다 · 此=이것 | I24: N | O24: 보통
A25: 24 | B25: 4 | C25: 459 | D25: 來弊舖賣此 | E25: 金相公老實人 | F25: 與俺情同嫡親兄弟 | H25: 金=쇠붙이 · 相=서로 · 公=공변되다·귀인 · 老=늙다 · 實=차다 · 人=사람 | I25: N | O25: 보통
A26: 25 | B26: 4 | C26: 460 | D26: 金相公老實人 | E26: 與俺情同嫡親兄弟 | F26: 俺以三兩五分紋銀收買 | H26: 與=주다 · 同=같다 | I26: Y | J26: SD-6 문화·제도 | K26: TD-6 기타 | L26: 情同嫡親兄弟 | M26: 친분 | N26: 친족 관계가 교분의 정도로 옮겨감(직유) | O26: 보통
A27: 26 | B27: 4 | C27: 461 | D27: 與俺情同嫡親兄弟 | E27: 俺以三兩五分紋銀收買 | F27: 改裝時直不下七兩 | G27: 買 銀 | H27: 以=~로써 · 三=셋 · 兩=두 개·무게 단위 · 五=다섯 · 分=나누다 · 銀=은 · 收=거두다 · 買=사다 | I27: N | O27: 보통
A28: 27 | B28: 4 | C28: 462 | D28: 俺以三兩五分紋銀收買 | E28: 改裝時直不下七兩 | F28: 但無畵 | H28: 時=때 · 不=아니다 · 下=아래쪽 · 七=일곱 · 兩=두 개·무게 단위 | I28: N | O28: 보통
A29: 28 | B29: 4 | C29: 469 | D29: 主人亦設酒果 | E29: 大約我國書畵 | F29: 什無年號 | H29: 大=크다 · 我=나 · 國=나라 · 書=글 | I29: N | O29: 보통
A30: 29 | B30: 4 | C30: 470 | D30: 大約我國書畵 | E30: 什無年號 | F30: 又不肯書名字 | G30: 什 | H30: 什=열 · 無=없다 · 年=해 | I30: N | O30: 보통
A31: 30 | B31: 4 | C31: 471 | D31: 什無年號 | E31: 又不肯書名字 | F31: 詩軸所題 | H31: 又=또 · 不=아니다 · 書=글 · 名=이름 | I31: N | O31: 보통
A32: 31 | B32: 4 | C32: 492 | D32: 故到處向人 | E32: 輒呼炒卵二字 | F32: 以試其舌頭利澀 | H32: 二=둘 | I32: N | O32: 보통
A33: 32 | B33: 4 | C33: 493 | D33: 輒呼炒卵二字 | E33: 以試其舌頭利澀 | F33: 因此號鄭爲炒卵公 | G33: 利 | H33: 以=~로써 · 其=그 · 舌=혀 · 頭=머리 · 利=날이 날카롭다 → 이롭다 | I33: Y | J33: SD-2 신체·감각 | K33: TD-7 경물·감각 | L33: 舌頭利澀 | M33: 발음의 감각 | N33: 혀의 매끄러움과 껄끄러움이 발음의 정확도로 옮겨감 | O33: 보통
A34: 33 | B34: 4 | C34: 494 | D34: 以試其舌頭利澀 | E34: 因此號鄭爲炒卵公 | F34: 我東優戱爲假面 | H34: 因=말미암다 · 此=이것 · 爲=하다·되다 · 公=공변되다·귀인 | I34: N | O34: 보통
A35: 34 | B35: 4 | C35: 502 | D35: 相與大笑 | E35: 備說其由 | F35: 欲贈其價 | H35: 其=그 | I35: N | O35: 보통
A36: 35 | B36: 4 | C36: 503 | D36: 備說其由 | E36: 欲贈其價 | F36: 主人大慚曰 | G36: 價 | H36: 欲=하고자 하다 · 其=그 · 價=값 | I36: N | O36: 보통
A37: 36 | B37: 4 | C37: 504 | D37: 欲贈其價 | E37: 主人大慚曰 | F37: 此非酒飯店 | H37: 主=주인 · 人=사람 · 大=크다 · 曰=말하다 | I37: N | O37: 보통
A38: 37 | B38: 36 | C38: 27 | D38: 朝氣微凉 | E38: 城外臨水開市 | F38: 百貨塡咽 | H38: 城=성 · 外=바깥 · 水=물 · 開=열다 · 市=저자 | I38: N | O38: 보통
A39: 38 | B39: 36 | C39: 28 | D39: 城外臨水開市 | E39: 百貨塡咽 | F39: 車馬縱橫 | G39: 貨 | H39: 百=일백 · 貨=사고파는 물건 · 塡=메워 채우다 · 咽=목구멍 | I39: Y | J39: SD-2 신체·감각 | K39: TD-1 축적·유통 | L39: 百貨塡咽 | M39: 혼잡 | N39: 목구멍이 막힘이 시장의 물화 집중으로 옮겨감 | O39: 높음
A40: 39 | B40: 36 | C40: 29 | D40: 百貨塡咽 | E40: 車馬縱橫 | F40: 自入市中 | H40: 車=수레 · 馬=말 · 縱=줄을 놓다 | I40: N | O40: 보통
...

Sheet 옥갑야화
A1: 연번 | B1: 문단 | C1: 절번호 | D1: 앞 문맥(참고) | E1: ★ 판정 대상 절 ★ | F1: 뒤 문맥(참고) | G1: 트리거 | H1: 주요 글자의 기본 의미 | I1: 직역 | J1: 의역 | K1: 은유 여부 | L1: 원천 영역 | M1: 목표 영역 | N1: 원천 어휘 | O1: 목표 개념 | P1: 판정 근거 | Q1: 확신도 | R1: 비고
A2: 1 | B2: 2 | C2: 3 | D2: 與諸裨連牀夜語 | E2: 燕京舊時風俗淳厚 | F2: 譯輩雖萬金能相假貸 | H2: 燕=제비·연나라 · 京=서울 · 舊=옛 · 時=때 · 風=바람 · 俗=풍속 · 厚=두껍다 | I2: 연경의 옛 풍속은 순박하고 두터워 | J2: 연경의 옛 인심은 순박하고 후해서 | K2: Y | L2: SD-1 자연·물질 | M2: TD-5 문명·제도 | N2: 淳厚 | O2: 인심 | P2: 액체의 순도와 두께로 풍속을 말함 | Q2: 낮음
A3: 2 | B3: 2 | C3: 4 | D3: 燕京舊時風俗淳厚 | E3: 譯輩雖萬金能相假貸 | F3: 今則彼以欺詐爲能事 | G3: 萬金 | H3: 譯=통역하다 · 輩=무리 · 雖=비록 · 萬=일만 · 金=쇠붙이 · 能=능하다 · 相=서로 | I3: 역관 무리가 만금이라도 서로 빌려줄 수 있었다 | J3: 역관들끼리 만금이라도 서로 꾸어 주었다 | K3: N | Q3: 보통
A4: 3 | B4: 2 | C4: 5 | D4: 譯輩雖萬金能相假貸 | E4: 今則彼以欺詐爲能事 | F4: 而其 | H4: 今=이제 · 則=곧 · 彼=저 · 以=~로써 · 爲=하다·되다 · 能=능하다 · 事=일 | I4: 이제는 저들이 속임수를 능사로 삼는데 | J4: 이제는 저들이 속임수를 능사로 삼는데 | K4: N | Q4: 보통
A5: 4 | B5: 2 | C5: 14 | D5: 對曰 | E5: 渡江 | F5: 時潛挾他人銀 | H5: 江=큰 강 | I5: 강을 건널 | J5: 강을 건널 | K5: N | Q5: 보통
A6: 5 | B6: 2 | C6: 15 | D6: 渡江 | E6: 時潛挾他人銀 | F6: 事發 | G6: 銀 | H6: 時=때 · 潛=물속에 잠기다 · 人=사람 · 銀=은 | I6: 때 남의 은을 몰래 끼고 있다가 | J6: 때 남의 은을 몰래 지니고 있다가 | K6: Y | L6: SD-1 자연·물질 | M6: TD-1 축적·유통 | N6: 潛 | O6: 은닉 | P6: 물속에 잠김이 은밀한 소지로 옮겨감 | Q6: 보통
A7: 6 | B7: 2 | C7: 16 | D7: 時潛挾他人銀 | E7: 事發 | F7: 倂已包沒于官 | H7: 事=일 | I7: 일이 발각되어 | J7: 일이 들통나 | K7: N | Q7: 보통
A8: 7 | B8: 2 | C8: 24 | D8: 奪 | E8: 刀問曰 | F8: 所沒銀幾何 | H8: 問=묻다 · 曰=말하다 | I8: 칼을 빼앗고 물었다 | J8: 칼을 빼앗고 물었다 | K8: N | Q8: 보통
A9: 8 | B9: 2 | C9: 25 | D9: 刀問曰 | E9: 所沒銀幾何 | F9: 曰 | G9: 銀 | H9: 所=바·곳 · 沒=물에 빠져 가라앉다 · 銀=은 · 幾=몇 · 何=무엇 | I9: 몰수당한 은이 얼마인가 | J9: 몰수당한 은이 얼마나 되는가 | K9: Y | L9: SD-1 자연·물질 | M9: TD-1 축적·유통 | N9: 沒 | O9: 몰수 | P9: 물에 잠겨 사라짐이 재산 몰수로 옮겨감 | Q9: 보통
A10: 9 | B10: 2 | C10: 26 | D10: 所沒銀幾何 | E10: 曰 | F10: 三千兩 | H10: 曰=말하다 | I10: 말하기를 | J10: 대답하기를 | K10: N | Q10: 보통
A11: 10 | B11: 2 | C11: 29 | D11: 主顧慰曰 | E11: 大丈夫獨患無身 | F11: 何患無銀 | H11: 大=크다 · 夫=사내·무릇 · 獨=홀로 · 無=없다 · 身=몸 | I11: 대장부는 오직 몸 없음을 근심할 뿐 | J11: 대장부가 걱정할 것은 몸뿐이지 | K11: N | Q11: 보통
A12: 11 | B12: 2 | C12: 30 | D12: 大丈夫獨患無身 | E12: 何患無銀 | F12: 今死不還 | G12: 銀 | H12: 何=무엇 · 無=없다 · 銀=은 | I12: 어찌 은 없음을 근심하는가 | J12: 어찌 은이 없음을 걱정하는가 | K12: N | Q12: 보통
A13: 12 | B13: 2 | C13: 31 | D13: 何患無銀 | E13: 今死不還 | F13: 將如妻子何 | H13: 今=이제 · 死=죽다 · 不=아니다 · 還=돌아오다 | I13: 이제 죽어 돌아가지 않으면 | J13: 이제 죽어 돌아가지 않으면 | K13: N | Q13: 보통
A14: 13 | B14: 2 | C14: 33 | D14: 將如妻子何 | E14: 吾貸 | F14: 君萬金 | H14: 吾=나 | I14: 내가 빌려주겠다 | J14: 내가 빌려주겠다 | K14: N | Q14: 보통
A15: 14 | B15: 2 | C15: 34 | D15: 吾貸 | E15: 君萬金 | F15: 五年貨殖 | G15: 萬金 | H15: 君=임금·그대 · 萬=일만 · 金=쇠붙이 | I15: 그대에게 만금을 | J15: 그대에게 만금을 | K15: N | Q15: 보통
A16: 15 | B16: 2 | C16: 35 | D16: 君萬金 | E16: 五年貨殖 | F16: 可復得萬金 | G16: 貨殖 | H16: 五=다섯 · 年=해 · 貨=사고파는 물건 · 殖=초목이 자라 불다 | I16: 오 년을 재화로 불리면 | J16: 오 년만 굴리면 | K16: Y | L16: SD-1 자연·물질 | M16: TD-1 축적·유통 | N16: 殖 | O16: 재화 증식 | P16: 초목의 생장이 재화의 불림으로 옮겨감 | Q16: 높음
A17: 16 | B17: 2 | C17: 36 | D17: 五年貨殖 | E17: 可復得萬金 | F17: 以本銀償我 | G17: 萬金 | H17: 可=옳다·가하다 · 得=얻다 · 萬=일만 · 金=쇠붙이 | I17: 다시 만금을 얻을 수 있다 | J17: 다시 만금을 얻을 수 있으니 | K17: N | Q17: 보통
A18: 17 | B18: 2 | C18: 37 | D18: 可復得萬金 | E18: 以本銀償我 | F18: 譯旣得萬金 | G18: 銀 償 | H18: 以=~로써 · 本=나무의 뿌리 · 銀=은 · 償=갚다 · 我=나 | I18: 본은으로 나에게 갚으라 | J18: 원금만 내게 갚으라 | K18: Y | L18: SD-1 자연·물질 | M18: TD-1 축적·유통 | N18: 本銀 | O18: 원금 | P18: 초목의 뿌리가 자본의 근원으로 옮겨감 | Q18: 보통
A19: 18 | B19: 2 | C19: 38 | D19: 以本銀償我 | E19: 譯旣得萬金 | F19: 遂大貿而還 | G19: 萬金 | H19: 譯=통역하다 · 旣=이미 · 得=얻다 · 萬=일만 · 金=쇠붙이 | I19: 역관이 이미 만금을 얻어 | J19: 역관은 만금을 얻자 | K19: N | Q19: 보통
A20: 19 | B20: 2 | C20: 39 | D20: 譯旣得萬金 | E20: 遂大貿而還 | F20: 當時未有識之者 | H20: 遂=마침내 · 大=크다 · 而=말 잇는 조사 · 還=돌아오다 | I20: 마침내 크게 무역해 돌아왔다 | J20: 크게 무역해 돌아왔다 | K20: N | Q20: 보통
A21: 20 | B21: 2 | C21: 41 | D21: 當時未有識之者 | E21: 莫不神其才 | F21: 五年中遂致鉅富 | H21: 莫=없다 · 不=아니다 · 神=신령 · 其=그 | I21: 그 재주를 신통히 여기지 않는 이가 없었다 | J21: 그 재주를 신통히 여기지 않는 이가 없었다 | K21: Y | L21: SD-6 문화·제도 | M21: TD-3 인식·진위 | N21: 神 | O21: 경탄 | P21: 신격 관념이 재능 평가로 옮겨감 | Q21: 낮음
A22: 21 | B22: 2 | C22: 42 | D22: 莫不神其才 | E22: 五年中遂致鉅富 | F22: 乃自削籍譯院 | G22: 富 | H22: 五=다섯 · 年=해 · 中=가운데 · 遂=마침내 · 致=이르게 하다 · 鉅=큰 쇠 · 富=재물이 넉넉하다 | I22: 오 년 만에 마침내 큰 부자가 되었다 | J22: 오 년 만에 큰 부자가 되었다 | K22: N | Q22: 보통
A23: 22 | B23: 2 | C23: 43 | D23: 五年中遂致鉅富 | E23: 乃自削籍譯院 | F23: 不復入燕 | H23: 乃=이에 · 自=스스로 · 籍=문서 · 譯=통역하다 | I23: 이에 스스로 역원의 적을 깎고 | J23: 그러고는 스스로 역관 명부에서 이름을 지우고 | K23: N | Q23: 보통
A24: 23 | B24: 3 | C24: 2 | D24: 有言李知事樞 | E24: 近世名譯也 | F24: 平居口未嘗言錢 | H24: 世=세상 · 名=이름 · 譯=통역하다 · 也=단정하는 조사 | I24: 근세의 이름난 역관이다 | J24: 근세의 이름난 역관이다 | K24: N | Q24: 보통
A25: 24 | B25: 3 | C25: 3 | D25: 近世名譯也 | E25: 平居口未嘗言錢 | F25: 出入燕京四十餘年 | G25: 錢 | H25: 平=평평하다 · 居=머물러 살다 · 口=입 · 未=아직 ~않다 · 言=말하다 · 錢=엽전 | I25: 평소에 입으로 돈을 말한 적이 없고 | J25: 평소 입으로 돈을 말한 적이 없고 | K25: N | Q25: 보통
A26: 25 | B26: 3 | C26: 4 | D26: 平居口未嘗言錢 | E26: 出入燕京四十餘年 | F26: 手未嘗執銀 | H26: 出=나가다 · 入=들다 · 燕=제비·연나라 · 京=서울 · 四=넷 · 十=열 · 餘=남다 · 年=해 | I26: 연경을 사십여 년 드나들면서도 | J26: 사십여 년 연경을 드나들면서도 | K26: N | Q26: 보통
A27: 26 | B27: 3 | C27: 5 | D27: 出入燕京四十餘年 | E27: 手未嘗執銀 | F27: 有愷悌君子之風 | G27: 銀 | H27: 手=손 · 未=아직 ~않다 · 銀=은 | I27: 손으로 은을 쥔 적이 없어 | J27: 손으로 은을 쥔 적이 없어 | K27: N | Q27: 보통
A28: 27 | B28: 3 | C28: 6 | D28: 手未嘗執銀 | E28: 有愷悌君子之風 | H28: 有=있다 · 君=임금·그대 · 子=아들 · 之=가다 (조사로도 쓰임) · 風=바람 | I28: 화락한 군자의 풍모가 있었다 | J28: 온화한 군자의 풍모가 있었다 | K28: Y | L28: SD-1 자연·물질 | M28: TD-5 문명·제도 | N28: 風 | O28: 풍모 | P28: 바람이 인격의 기풍으로 옮겨감 | Q28: 보통
A29: 28 | B29: 4 | C29: 5 | D29: 嘗遊娼館 | E29: 女隨色第 | F29: 價有千金者 | H29: 色=빛깔 | I29: 여자는 미모에 따라 등급이 있어 | J29: 여자는 미모에 따라 등급이 매겨져 | K29: N | Q29: 보통
A30: 29 | B30: 4 | C30: 6 | D30: 女隨色第 | E30: 價有千金者 | F30: 洪以千金求薦枕 | G30: 千金 價 | H30: 價=값 · 有=있다 · 千=일천 · 金=쇠붙이 · 者=~하는 것·사람 | I30: 값이 천금인 자가 있었다 | J30: 값이 천금인 이도 있었다 | K30: N | Q30: 보통
A31: 30 | B31: 4 | C31: 7 | D31: 價有千金者 | E31: 洪以千金求薦枕 | F31: 女 | G31: 千金 | H31: 以=~로써 · 千=일천 · 金=쇠붙이 · 求=구하다 | I31: 홍이 천금으로 잠자리를 구하니 | J31: 홍순언이 천금을 내고 잠자리를 청하니 | K31: N | Q31: 보통
A32: 31 | B32: 4 | C32: 8 | D32: 洪以千金求薦枕 | E32: 女 | F32: 方二八 | I32: 여자는 | J32: 그 여자는 | K32: N | Q32: 보통
A33: 32 | B33: 4 | C33: 11 | D33: 有殊色 | E33: 對君泣曰 | F33: 奴所以索高價者 | H33: 君=임금·그대 · 泣=울다 · 曰=말하다 | I33: 그대를 향해 울며 말했다 | J33: 그를 향해 울며 말했다 | K33: N | Q33: 보통
A34: 33 | B34: 4 | C34: 12 | D34: 對君泣曰 | E34: 奴所以索高價者 | F34: 誠謂天下皆慳男 | G34: 價 | H34: 所=바·곳 · 以=~로써 · 高=높다 · 價=값 · 者=~하는 것·사람 | I34: 제가 높은 값을 부른 까닭은 | J34: 제가 값을 높이 부른 까닭은 | K34: Y | L34: SD-3 공간·방위 | M34: TD-1 축적·유통 | N34: 高價 | O34: 가격 | P34: 값의 크기를 공간의 높낮이로 나타냄 | Q34: 보통
A35: 34 | B35: 4 | C35: 13 | D35: 奴所以索高價者 | E35: 誠謂天下皆慳男 | F35: 無肯捐千金者 | H35: 謂=이르다 · 天=하늘 · 下=아래쪽 · 皆=모두 | I35: 참으로 천하에 인색한 사내뿐이어서 | J35: 천하가 다 인색한 사내뿐이라 | K35: N | Q35: 보통
A36: 35 | B36: 4 | C36: 14 | D36: 誠謂天下皆慳男 | E36: 無肯捐千金者 | F36: 祈以免斯須之辱 | G36: 千金 | H36: 無=없다 · 千=일천 · 金=쇠붙이 · 者=~하는 것·사람 | I36: 천금을 선뜻 내놓을 자가 없으리라 여겨 | J36: 천금을 선뜻 내놓을 이가 없으리라 여겨 | K36: N | Q36: 보통
A37: 36 | B37: 4 | C37: 15 | D37: 無肯捐千金者 | E37: 祈以免斯須之辱 | F37: 一日 | H37: 以=~로써 · 之=가다 (조사로도 쓰임) | I37: 잠깐의 욕됨이나마 면하기를 빌었기 때문입니다 | J37: 잠시나마 욕을 면해 보려 한 것입니다 | K37: N | Q37: 보통
A38: 37 | B38: 4 | C38: 19 | D38: 本欲以愚館主 | E38: 一以望天下有義氣人 | F38: 贖奴作箕帚妾 | H38: 一=하나 · 以=~로써 · 望=바라보다 · 天=하늘 · 下=아래쪽 · 有=있다 · 義=옳음 · 氣=기운 · 人=사람 | I38: 하나는 천하에 의기 있는 사람을 만나기를 바랐습니다 | J38: 하나는 천하에 의기 있는 이를 만나기를 바랐습니다 | K38: N | Q38: 보통
A39: 38 | B39: 4 | C39: 20 | D39: 一以望天下有義氣人 | E39: 贖奴作箕帚妾 | F39: 奴入娼館五日 | G39: 贖 | H39: 贖=값을 치러 되찾다 | I39: 저를 속량하여 아내로 삼아 주십시오 | J39: 저를 속량하여 거두어 주십시오 | K39: Y | L39: SD-6 문화·제도 | M39: TD-5 문명·제도 | N39: 箕帚 | O39: 아내 | P39: 가사 도구가 혼인 신분을 대신함 | Q39: 보통
A40: 39 | B40: 4 | C40: 21 | D40: 贖奴作箕帚妾 | E40: 奴入娼館五日 | F40: 無敢以千金來者 | H40: 入=들다 · 五=다섯 · 日=해·날 | I40: 제가 기방에 든 지 닷새인데 | J40: 제가 기방에 든 지 닷새인데 | K40: N | Q40: 보통
...

Sheet 행재잡록
A1: 연번 | B1: 문단 | C1: 절번호 | D1: 앞 문맥(참고) | E1: ★ 판정 대상 절 ★ | F1: 뒤 문맥(참고) | G1: 트리거 | H1: 주요 글자의 기본 의미 | I1: 직역 | J1: 의역 | K1: 은유 여부 | L1: 원천 영역 | M1: 목표 영역 | N1: 원천 어휘 | O1: 목표 개념 | P1: 판정 근거 | Q1: 확신도 | R1: 비고
A2: 1 | B2: 2 | C2: 23 | D2: 故其所都燕京曰京師 | E2: 其巡幸之所曰行在 | F2: 我效土物之儀曰職貢 | H2: 其=그 · 之=가다 (조사로도 쓰임) · 所=바·곳 · 曰=말하다 · 行=걸어가다 · 在=있다 | I2: 그 순행하는 곳을 행재라 한다 | J2: 황제가 순행하는 곳을 행재라 하고 | K2: N | Q2: 보통
A3: 2 | B3: 2 | C3: 24 | D3: 其巡幸之所曰行在 | E3: 我效土物之儀曰職貢 | F3: 其語當宁曰天子 | G3: 貢 | H3: 我=나 · 物=물건 · 之=가다 (조사로도 쓰임) · 曰=말하다 · 貢=바치는 물건 | I3: 우리가 토산물을 바치는 의례를 직공이라 한다 | J3: 우리가 토산물을 바치는 것을 직공이라 하며 | K3: N | Q3: 보통
A4: 3 | B4: 2 | C4: 25 | D4: 我效土物之儀曰職貢 | E4: 其語當宁曰天子 | F4: 其朝 | H4: 其=그 · 語=말하다 · 當=마땅하다 · 曰=말하다 · 天=하늘 · 子=아들 | I4: 그 임금을 일컬어 천자라 한다 | J4: 그 임금을 천자라 부른다 | K4: N | Q4: 보통
A5: 4 | B5: 2 | C5: 36 | D5: 昔倭人覆我疆域 | E5: 我神宗皇帝提天下之師東援之 | F5: 竭帑銀以 | H5: 我=나 · 神=신령 · 天=하늘 · 下=아래쪽 · 之=가다 (조사로도 쓰임) · 東=동쪽 | I5: 우리 신종 황제가 천하의 군사를 이끌어 동으로 도왔다 | J5: 신종 황제가 천하의 군대를 이끌고 동쪽을 도왔고 | K5: Y | L5: SD-2 신체·감각 | M5: TD-2 권력·지배 | N5: 提天下之師 | O5: 군대 통솔 | P5: 손으로 끎이 군대의 통솔로 옮겨감 | Q5: 보통
A6: 5 | B6: 2 | C6: 37 | D6: 我神宗皇帝提天下之師東援之 | E6: 竭帑銀以 | F6: 供師旅 | G6: 銀 | H6: 竭=물이 다 마르다 · 銀=은 · 以=~로써 | I6: 국고의 은을 다 말려 | J6: 나라 곳간의 은을 바닥까지 털어 | K6: Y | L6: SD-1 자연·물질 | M6: TD-1 축적·유통 | N6: 竭帑銀 | O6: 국고 고갈 | P6: 물이 마름이 국고의 소진으로 옮겨감 | Q6: 높음
A7: 6 | B7: 2 | C7: 38 | D7: 竭帑銀以 | E7: 供師旅 | F7: 復我三都 | H7: 旅=나그네 | I7: 군대에 대주었다 | J7: 군대를 먹였다 | K7: N | Q7: 보통
A8: 7 | B8: 2 | C8: 50 | D8: 所以加惠我國者 | E8: 亦累葉矣 | F8: 金非土產則蠲之 | H8: 亦=또한 · 矣=마치는 조사 | I8: 또한 여러 대에 걸쳤다 | J8: 그것도 여러 대에 걸친 일이다 | K8: Y | L8: SD-1 자연·물질 | M8: TD-5 문명·제도 | N8: 累葉 | O8: 여러 대 | P8: 잎이 포개짐이 세대의 누적으로 옮겨감 | Q8: 높음
A9: 8 | B9: 2 | C9: 51 | D9: 亦累葉矣 | E9: 金非土產則蠲之 | F9: 綵馬衰小則 | G9: 產 | H9: 金=쇠붙이 · 非=아니다 · 則=곧 · 之=가다 (조사로도 쓰임) | I9: 금은 토산이 아니므로 면제해 주고 | J9: 금은 우리 토산이 아니라 하여 면제해 주고 | K9: N | Q9: 보통
A10: 9 | B10: 2 | C10: 52 | D10: 金非土產則蠲之 | E10: 綵馬衰小則 | F10: 免之 | H10: 馬=말 · 衰=초목이 시들다 · 小=작다 · 則=곧 | I10: 무늬 말이 여위고 작으면 | J10: 바치는 말이 여위고 작으면 | K10: N | Q10: 보통
A11: 10 | B11: 2 | C11: 64 | D11: 命班于大臣之列 | E11: 其聽戱得比廷臣而宴賚之 | F11: 又詔永蠲正貢外 | H11: 其=그 · 得=얻다 · 臣=신하 · 而=말 잇는 조사 · 之=가다 (조사로도 쓰임) | I11: 그 연극 구경을 조정 신하에 견주어 잔치와 하사를 베풀었다 | J11: 연극 구경도 조정 신하와 같이 대접하고 잔치와 상을 내렸다 | K11: N | Q11: 보통
A12: 11 | B12: 2 | C12: 65 | D12: 其聽戱得比廷臣而宴賚之 | E12: 又詔永蠲正貢外 | F12: 別使方物 | G12: 貢 | H12: 又=또 · 正=바르다 · 貢=바치는 물건 · 外=바깥 | I12: 또 조서를 내려 정공 밖의 것을 길이 면제하고 | J12: 또 조서를 내려 정례 공물 외의 것을 영구히 면제하고 | K12: N | Q12: 보통
A13: 12 | B13: 2 | C13: 66 | D13: 又詔永蠲正貢外 | E13: 別使方物 | F13: 此實曠世盛典 | H13: 使=시키다 · 方=모나다·바야흐로 · 物=물건 | I13: 별사의 방물도 | J13: 별사의 방물까지 없앴으니 | K13: N | Q13: 보통
A14: 13 | B14: 2 | C14: 84 | D14: 在大國不過爲卹小 | E14: 柔遠之政 | F14: 則雖代蠲一貢 | H14: 遠=멀다 · 之=가다 (조사로도 쓰임) | I14: 먼 나라를 부드럽게 하는 정사는 | J14: 먼 나라를 어루만지는 정사란 | K14: Y | L14: SD-2 신체·감각 | M14: TD-2 권력·지배 | N14: 柔遠 | O14: 회유 | P14: 부드러움의 촉감이 원방 회유책으로 옮겨감 | Q14: 보통
A15: 14 | B15: 2 | C15: 85 | D15: 柔遠之政 | E15: 則雖代蠲一貢 | F15: 歲免一幣 | G15: 貢 | H15: 則=곧 · 雖=비록 · 一=하나 · 貢=바치는 물건 | I15: 비록 대대로 한 차례 공물을 면제하고 | J15: 한 대에 한 번 공물을 면해 주고 | K15: N | Q15: 보통
A16: 15 | B16: 2 | C16: 86 | D16: 則雖代蠲一貢 | E16: 歲免一幣 | F16: 是惠也 | H16: 歲=한 해 · 一=하나 · 幣=예물로 쓰는 비단 | I16: 한 해에 한 번 폐물을 면제해도 | J16: 한 해에 한 번 예물을 면해 주어도 | K16: N | Q16: 보통
A17: 16 | B17: 8 | C17: 6 | D17: 會同理藩院司員等帶領朝鮮使臣正使朴副使鄭書 | E17: 狀官趙等 | F17: 前詣札什倫布 | H17: 官=벼슬 · 等=무리 | I17: 서장관 조 아무개 등이 | J17: 서장관 조 아무개 등을 데리고 | K17: N | Q17: 보통
A18: 17 | B18: 8 | C18: 7 | D18: 狀官趙等 | E18: 前詣札什倫布 | F18: 拜見額爾德尼 | G18: 什 | H18: 前=앞 · 什=열 · 布=베 | I18: 찰십륜포로 나아가 | J18: 찰십륜포로 가서 | K18: N | Q18: 보통
A19: 18 | B19: 8 | C19: 8 | D19: 前詣札什倫布 | E19: 拜見額爾德尼 | F19: 行禮後 | H19: 見=보다 · 德=덕 | I19: 액이덕니를 배견하고 | J19: 반선을 뵙고 | K19: N | Q19: 보통
A20: 19 | B20: 8 | C20: 11 | D20: 令坐吃茶 | E20: 詢問該國遠近 | F20: 幷入貢緣由 | H20: 問=묻다 · 國=나라 · 遠=멀다 | I20: 그 나라의 멀고 가까움을 물으며 | J20: 그 나라가 얼마나 먼지를 묻고 | K20: N | Q20: 보통
A21: 20 | B21: 8 | C21: 12 | D21: 詢問該國遠近 | E21: 幷入貢緣由 | F21: 該使臣答以 | G21: 貢 | H21: 入=들다 · 貢=바치는 물건 | I21: 아울러 입공한 연유를 물으니 | J21: 아울러 입공한 까닭을 물으니 | K21: N | Q21: 보통
A22: 21 | B22: 8 | C22: 13 | D22: 幷入貢緣由 | E22: 該使臣答以 | F22: 因皇上七旬大慶 | H22: 使=시키다 · 臣=신하 · 答=대답하다 · 以=~로써 | I22: 그 사신이 답하기를 | J22: 사신이 대답하기를 | K22: N | Q22: 보통
A23: 22 | B23: 9 | C23: 2 | D23: 使臣見班禪事 | E23: 余具載之 | F23: 札什倫布記及見禮部奏聞 | H23: 余=나 · 之=가다 (조사로도 쓰임) | I23: 내가 그것을 갖추어 적었다 | J23: 내가 그 일을 자세히 적어 두었다 | K23: N | Q23: 보통
A24: 23 | B24: 9 | C24: 3 | D24: 余具載之 | E24: 札什倫布記及見禮部奏聞 | F24: 其稱拜見額爾德尼 | G24: 什 | H24: 什=열 · 布=베 · 及=미치다 · 見=보다 · 禮=예 · 聞=듣다 | I24: 찰십륜포기와 예부의 주문을 보니 | J24: 찰십륜포기와 예부의 주문을 보건대 | K24: N | Q24: 보통
A25: 24 | B25: 9 | C25: 4 | D25: 札什倫布記及見禮部奏聞 | E25: 其稱拜見額爾德尼 | F25: 給與使臣等物件 | H25: 其=그 · 稱=일컫다 · 見=보다 · 德=덕 | I25: 그 액이덕니를 배견했다 일컫고 | J25: 반선을 배견했다고 적고 | K25: N | Q25: 보통
A26: 25 | B26: 9 | C26: 11 | D26: 不得不爾 | E26: 第據吾所目擊者詳錄之 | F26: 以資山中曝背一粲 | H26: 吾=나 · 所=바·곳 · 目=눈 · 者=~하는 것·사람 · 之=가다 (조사로도 쓰임) | I26: 다만 내가 목격한 바에 따라 자세히 기록하여 | J26: 다만 내가 직접 본 대로 자세히 적어 | K26: N | Q26: 보통
A27: 26 | B27: 9 | C27: 12 | D27: 第據吾所目擊者詳錄之 | E27: 以資山中曝背一粲 | F27: 覽者 | G27: 資 | H27: 以=~로써 · 資=밑천 · 山=산 · 中=가운데 · 一=하나 | I27: 산중에서 등을 볕에 쬐는 웃음거리의 밑천으로 삼는다 | J27: 산중에서 볕이나 쬐며 웃을 거리로 삼는다 | K27: Y | L27: SD-6 문화·제도 | M27: TD-4 도덕·책무 | N27: 曝背 | O27: 미천한 정성 | P27: 등을 볕에 쬐는 고사가 하찮은 헌정으로 옮겨감 | Q27: 보통
A28: 27 | B28: 9 | C28: 13 | D28: 以資山中曝背一粲 | E28: 覽者 | F28: 當有以察之 | H28: 者=~하는 것·사람 | I28: 보는 이는 | J28: 보는 이는 | K28: N | Q28: 보통
A29: 28 | B29: 13 | C29: 4 | D29: 中國例相贈遺遠遊者 | E29: 必持此朝夕供養 | F29: 藏俗年例進貢 | H29: 必=반드시 · 此=이것 · 朝=아침·조정 | I29: 반드시 이를 지녀 아침저녁으로 공양한다 | J29: 반드시 이를 지니고 조석으로 공양한다 | K29: N | Q29: 보통
A30: 29 | B30: 13 | C30: 5 | D30: 必持此朝夕供養 | E30: 藏俗年例進貢 | F30: 首以佛一尊爲 | G30: 貢 | H30: 俗=풍속 · 年=해 · 進=나아가다 · 貢=바치는 물건 | I30: 티베트 풍속에 해마다 공물을 바치는데 | J30: 티베트 풍속에 해마다 공물을 바치는데 | K30: N | Q30: 보통
A31: 30 | B31: 13 | C31: 6 | D31: 藏俗年例進貢 | E31: 首以佛一尊爲 | F31: 方物 | H31: 以=~로써 · 一=하나 · 爲=하다·되다 | I31: 부처 한 존을 으뜸으로 삼아 | J31: 부처 한 존을 으뜸으로 삼아 | K31: N | Q31: 보통
A32: 31 | B32: 13 | C32: 18 | D32: 諸譯亦視同糞穢 | E32: 若將凂焉 | F32: 售銀九十兩 | H32: 若=같다 · 凂=물이 더러워지다 · 焉=어찌 | I32: 마치 더럽혀질 듯이 여겨 | J32: 더럽혀질까 꺼려 | K32: Y | L32: SD-1 자연·물질 | M32: TD-4 도덕·책무 | N32: 凂 | O32: 더럽혀짐 | P32: 물의 오염이 도덕적 더럽힘으로 옮겨감 | Q32: 보통
A33: 32 | B33: 13 | C33: 19 | D33: 若將凂焉 | E33: 售銀九十兩 | F33: 散之一行 | G33: 銀 | H33: 銀=은 · 九=아홉 · 十=열 · 兩=두 개·무게 단위 | I33: 은 아흔 냥에 팔아 | J33: 은 아흔 냥에 팔아 | K33: N | Q33: 보통
A34: 33 | B34: 13 | C34: 20 | D34: 售銀九十兩 | E34: 散之一行 | F34: 馬頭輩 | H34: 之=가다 (조사로도 쓰임) · 一=하나 · 行=걸어가다 | I34: 일행에게 나누어 주었다 | J34: 일행에게 나누어 주었다 | K34: N | Q34: 보통
A35: 34 | B35: 13 | C35: 21 | D35: 散之一行 | E35: 馬頭輩 | F35: 而不以此銀 | H35: 馬=말 · 頭=머리 · 輩=무리 | I35: 마두 무리에게 | J35: 마두들에게 | K35: N | Q35: 보통
A36: 35 | B36: 13 | C36: 22 | D36: 馬頭輩 | E36: 而不以此銀 | F36: 沽飮一盃酒 | G36: 銀 | H36: 而=말 잇는 조사 · 不=아니다 · 以=~로써 · 此=이것 · 銀=은 | I36: 그런데 이 은으로 | J36: 그런데 이 은으로는 | K36: N | Q36: 보통
A37: 36 | B37: 13 | C37: 23 | D37: 而不以此銀 | E37: 沽飮一盃酒 | F37: 潔則潔矣 | H37: 飮=마시다 · 一=하나 · 酒=술 | I37: 술 한 잔도 사 마시지 않았다 | J37: 술 한 잔도 사 마시지 않았다 | K37: N | Q37: 보통
A38: 37 | B38: 16 | C38: 3 | D38: 稱乾隆四十五年八月十二日內閣奉上諭朝鮮世守藩封 | E38: 素稱恭順 | F38: 歲時職貢 | H38: 稱=일컫다 | I38: 본디 공순하다 일컬어져 | J38: 본디 공순하다 일컬어져 | K38: N | Q38: 보통
A39: 38 | B39: 16 | C39: 4 | D39: 素稱恭順 | E39: 歲時職貢 | F39: 祗愼可嘉 | G39: 貢 | H39: 歲=한 해 · 時=때 · 貢=바치는 물건 | I39: 철마다 직공을 바치니 | J39: 철마다 공물을 바치니 | K39: N | Q39: 보통
A40: 39 | B40: 16 | C40: 5 | D40: 歲時職貢 | E40: 祗愼可嘉 | F40: 間遇特頒敕諭及資送歸國等事 | H40: 可=옳다·가하다 | I40: 공경하고 삼감이 가상하다 | J40: 그 공경함이 가상하다 | K40: N | Q40: 보통
...

Sheet 심세편
A1: 연번 | B1: 문단 | C1: 절번호 | D1: 앞 문맥(참고) | E1: ★ 판정 대상 절 ★ | F1: 뒤 문맥(참고) | G1: 트리거 | H1: 주요 글자의 기본 의미 | I1: 직역 | J1: 의역 | K1: 은유 여부 | L1: 원천 영역 | M1: 목표 영역 | N1: 원천 어휘 | O1: 목표 개념 | P1: 판정 근거 | Q1: 확신도 | R1: 비고
A2: 1 | B2: 2 | C2: 22 | D2: 道 | E2: 逢御史汪道昆 | F2: 屛息路左 | H2: 史=사관·역사 · 道=길 | I2: 어사 왕도곤을 만나 | J2: 어사 왕도곤을 만나자 | K2: N | Q2: 보통
A3: 2 | B3: 2 | C3: 23 | D3: 逢御史汪道昆 | E3: 屛息路左 | F3: 瞻望行塵 | G3: 息 | H3: 屛=숨을 죽이다 · 息=숨쉬다 · 路=길 | I3: 길 왼편에서 숨을 죽이고 | J3: 길가에 비켜서 숨을 죽인 채 | K3: Y | L3: SD-2 신체·감각 | M3: TD-2 권력·지배 | N3: 屛息 | O3: 위축 | P3: 숨을 죽임이 권세 앞의 위축으로 옮겨감 | Q3: 보통
A4: 3 | B4: 2 | C4: 24 | D4: 屛息路左 | E4: 瞻望行塵 | F4: 猶以爲榮 | H4: 望=바라보다 · 行=걸어가다 | I4: 가는 먼지를 바라보며 | J4: 지나가는 먼지를 바라보면서도 | K4: N | Q4: 보통
A5: 4 | B5: 2 | C5: 109 | D5: 始知衣冠士族幷在中原 | E5: 禮儀 | F5: 富盛 | H5: 禮=예 | I5: 예의 | J5: 예의와 | K5: N | Q5: 보통
A6: 5 | B6: 2 | C6: 110 | D6: 禮儀 | E6: 富盛 | F6: 人物殷阜 | G6: 富 | H6: 富=재물이 넉넉하다 | I6: 부성함 | J6: 부유함이며 | K6: N | Q6: 보통
A7: 6 | B7: 2 | C7: 111 | D7: 富盛 | E7: 人物殷阜 | F7: 耳目所識 | H7: 人=사람 · 物=물건 | I7: 인물이 넉넉하고 두텁다 | J7: 인물이 융성하다 | K7: Y | L7: SD-3 공간·방위 | M7: TD-5 문명·제도 | N7: 殷阜 | O7: 번성 | P7: 언덕의 두둑함이 인물의 성함으로 옮겨감 | Q7: 보통
A8: 7 | B8: 2 | C8: 131 | D8: 等百世之王 | E8: 莫之能違也 | F8: 旣無子貢之藝 | H8: 莫=없다 · 之=가다 (조사로도 쓰임) · 能=능하다 · 也=단정하는 조사 | I8: 어길 수 없다 | J8: 거스를 수 없다 | K8: N | Q8: 보통
A9: 8 | B9: 2 | C9: 132 | D9: 莫之能違也 | E9: 旣無子貢之藝 | F9: 季札之智 | G9: 貢 | H9: 旣=이미 · 無=없다 · 子=아들 · 貢=바치는 물건 · 之=가다 (조사로도 쓰임) | I9: 이미 자공의 재주가 없고 | J9: 자공 같은 재주도 없고 | K9: Y | L9: SD-6 문화·제도 | M9: TD-3 인식·진위 | N9: 子貢之藝 | O9: 재능 | P9: 역사 인물의 전거가 재능의 척도로 옮겨감 | Q9: 보통
A10: 9 | B10: 2 | C10: 133 | D10: 旣無子貢之藝 | E10: 季札之智 | F10: 則雖使笙鏞干 | H10: 之=가다 (조사로도 쓰임) · 智=슬기 | I10: 계찰의 지혜도 없으면 | J10: 계찰 같은 식견도 없으면 | K10: Y | L10: SD-6 문화·제도 | M10: TD-3 인식·진위 | N10: 季札之智 | O10: 식견 | P10: 역사 인물의 전거가 식견의 척도로 옮겨감 | Q10: 보통
A11: 10 | B11: 2 | C11: 238 | D11: 也 | E11: 彼將曰 | F11: 吾非利天下也 | H11: 彼=저 · 曰=말하다 | I11: 저들은 장차 말하리라 | J11: 저들은 이렇게 말할 것이다 | K11: N | Q11: 보통
A12: 11 | B12: 2 | C12: 239 | D12: 彼將曰 | E12: 吾非利天下也 | F12: 吾爲明室 | G12: 利 | H12: 吾=나 · 非=아니다 · 利=날이 날카롭다 → 이롭다 · 天=하늘 · 下=아래쪽 · 也=단정하는 조사 | I12: 나는 천하를 이롭게 하려는 것이 아니다 | J12: 나는 천하를 차지하려는 것이 아니라 | K12: N | Q12: 보통
A13: 12 | B13: 2 | C13: 240 | D13: 吾非利天下也 | E13: 吾爲明室 | F13: 復大仇雪大恥 | H13: 吾=나 · 爲=하다·되다 · 明=밝다 | I13: 나는 명나라 황실을 위하여 | J13: 명나라 황실을 위하여 | K13: N | Q13: 보통
A14: 13 | B14: 2 | C14: 288 | D14: 似若無所用心 | E14: 然其心以爲天下之小民 | F14: 薄其賦斂則安矣 | H14: 然=그러하다 · 其=그 · 心=마음 · 以=~로써 · 爲=하다·되다 · 天=하늘 · 下=아래쪽 · 之=가다 (조사로도 쓰임) · 小=작다 · 民=백성 | I14: 그러나 그 마음은 천하의 소민이 | J14: 그러나 속마음은 천하의 백성이 | K14: N | Q14: 보통
A15: 14 | B15: 2 | C15: 289 | D15: 然其心以爲天下之小民 | E15: 薄其賦斂則安矣 | F15: 安知不 | G15: 賦 | H15: 薄=얇다 · 其=그 · 賦=거두는 세 · 則=곧 · 安=편안하다 · 矣=마치는 조사 | I15: 그 부세를 얇게 하면 편안해진다고 여긴다 | J15: 세금만 가볍게 해 주면 만족하리라 여기는 것이다 | K15: Y | L15: SD-3 공간·방위 | M15: TD-2 권력·지배 | N15: 薄其賦斂 | O15: 경감 | P15: 두께의 얇음이 부세의 경감으로 옮겨감 | Q15: 보통
A16: 15 | B16: 2 | C16: 290 | D16: 薄其賦斂則安矣 | E16: 安知不 | F16: 反便乎我之帽服而不欲變我之制度乎 | H16: 安=편안하다 · 知=알다 · 不=아니다 | I16: 어찌 알겠는가 | J16: 어찌 알겠는가 | K16: N | Q16: 보통
A17: 16 | B17: 2 | C17: 296 | D17: 心 | E17: 其豪傑敢怒而不敢言其鄙佞 | F17: 因時義而爲身利 | H17: 其=그 · 而=말 잇는 조사 · 不=아니다 · 言=말하다 | I17: 그 호걸은 감히 노하되 감히 말하지 못하고 그 비루하고 아첨하는 자는 | J17: 호걸은 노하고도 말하지 못하며 비루하고 아첨하는 자는 | K17: N | Q17: 보통
A18: 17 | B18: 2 | C18: 297 | D18: 其豪傑敢怒而不敢言其鄙佞 | E18: 因時義而爲身利 | F18: 一以陰弱中土之士 | G18: 利 | H18: 因=말미암다 · 時=때 · 義=옳음 · 而=말 잇는 조사 · 爲=하다·되다 · 身=몸 · 利=날이 날카롭다 → 이롭다 | I18: 때의 명분을 빌려 제 몸의 이익으로 삼는다 | J18: 시세를 명분 삼아 제 잇속을 챙긴다 | K18: N | Q18: 보통
A19: 18 | B19: 2 | C19: 298 | D19: 因時義而爲身利 | E19: 一以陰弱中土之士 | F19: 一以顯受文敎之名 | H19: 一=하나 · 以=~로써 · 陰=그늘 · 弱=약하다 · 中=가운데 · 之=가다 (조사로도 쓰임) · 士=선비 | I19: 한편으로는 중원의 선비를 그늘로 약하게 하고 | J19: 한편으로는 중원의 선비를 은밀히 약화시키고 | K19: Y | L19: SD-1 자연·물질 | M19: TD-2 권력·지배 | N19: 陰弱 | O19: 은밀한 약화 | P19: 그늘이 은밀한 세력 약화로 옮겨감 | Q19: 높음
A20: 19 | B20: 2 | C20: 328 | D20: 皇帝私尊何累朱子 | E20: 而中州之士如此其恥之者 | F20: 葢有所激於陽尊而爲禦世之資耳 | H20: 而=말 잇는 조사 · 中=가운데 · 州=고을 · 之=가다 (조사로도 쓰임) · 士=선비 · 如=같다 · 此=이것 · 其=그 · 者=~하는 것·사람 | I20: 그런데 중원의 선비가 이처럼 부끄러워하는 것은 | J20: 그런데도 중원의 선비들이 이를 부끄러워하는 것은 | K20: N | Q20: 보통
A21: 20 | B21: 2 | C21: 329 | D21: 而中州之士如此其恥之者 | E21: 葢有所激於陽尊而爲禦世之資耳 | F21: 故時借一二集註之誤 | G21: 資 | H21: 有=있다 · 所=바·곳 · 於=~에 · 陽=볕 · 而=말 잇는 조사 · 爲=하다·되다 · 禦=막아내다 · 世=세상 · 之=가다 (조사로도 쓰임) · 資=밑천 | I21: 대개 겉으로 높이는 데 격분한 바가 있어 세상을 막는 밑천으로 삼을 뿐이다 | J21: 겉으로 떠받드는 태도에 자극받아 세상을 막는 구실로 삼을 뿐이다 | K21: Y | L21: SD-1 자연·물질 | M21: TD-2 권력·지배 | N21: 陽尊 | O21: 드러난 존숭 | P21: 볕이 표면적 존숭으로 옮겨감 | Q21: 보통
A22: 21 | B22: 2 | C22: 330 | D22: 葢有所激於陽尊而爲禦世之資耳 | E22: 故時借一二集註之誤 | F22: 以洩百年煩寃之氣 | H22: 故=까닭 · 時=때 · 一=하나 · 二=둘 · 之=가다 (조사로도 쓰임) | I22: 그러므로 때로 한두 집주의 잘못을 빌려 | J22: 그래서 때로 집주의 오류 한둘을 구실 삼아 | K22: Y | L22: SD-6 문화·제도 | M22: TD-3 인식·진위 | N22: 借集註之誤 | O22: 구실 삼음 | P22: 빌림이 구실의 차용으로 옮겨감 | Q22: 보통

Sheet 코드 정의
A1: 구분 | B1: 코드 | C1: 정의
A2: 원천 영역 | B2: SD-1 자연·물질 | C2: 물·지형·광물·기상 등 자연물과 그 운동
A3: 원천 영역 | B3: SD-2 신체·감각 | C3: 신체 부위와 그 작용, 감각 경험
A4: 원천 영역 | B4: SD-3 공간·방위 | C4: 상하·내외·원근 등 공간 배치와 방위
A5: 원천 영역 | B5: SD-4 사냥·전쟁 | C5: 목표물을 두고 경쟁적으로 추격·획득하는 행위
A6: 원천 영역 | B6: SD-5 운동·시간 | C6: 이동·방향·시간의 경과와 축적
A7: 원천 영역 | B7: SD-6 문화·제도 | C7: 역사 인물·전거, 신분 제도, 문자·복식 등 인공적 산물
A8: 원천 영역 | B8: (수사 기제) | C8: 원천 영역이 아니라 과장·역설·대조 등 표현을 조직하는 방식
A9: 목표 영역 | B9: TD-1 축적·유통 | C9: 재화의 축적, 유통, 경제 원리 자체
A10: 목표 영역 | B10: TD-2 권력·지배 | C10: 정치 권력, 지배와 복속, 국가 간 관계
A11: 목표 영역 | B11: TD-3 인식·진위 | C11: 앎, 판단, 진위 분별, 인식의 한계
A12: 목표 영역 | B12: TD-4 도덕·책무 | C12: 윤리 규범, 의무, 사회적 책임
... A15: 목표 영역 | B15: TD-6 기타 | C15: 위 여섯에 들지 않는 목표. 반드시 비고란에 무엇인지 적을 것

Sheet 트리거 해설
A1: 구분 | B1: 트리거 | C1: 기본 의미와 재화 관련성
A2: 복합어 | B2: 貿易 | C2: 물건을 바꾸다
A3: 복합어 | B3: 典當 | C3: 물건을 잡히고 돈을 빌리다
A4: 복합어 | B4: 包銀 | C4: 사행에 가져가는 정액의 은
A5: 복합어 | B5: 千金 | C5: 천 냥, 큰 재물
A6: 복합어 | B6: 萬金 | C6: 만 냥, 매우 큰 재물
A7: 복합어 | B7: 素封 | C7: 벼슬 없이 부유한 사람
A8: 복합어 | B8: 貨殖 | C8: 재물을 불리다
A9: 복합어 | B9: 財幣 | C9: 재물과 화폐
A10: 복합어 | B10: 財貨 | C10: 재물
A11: 단일자 | B11: 財 | C11: 재물 일반
A12: 단일자 | B12: 貨 | C12: 사고파는 물건
... A42: 단일자 | B42: 羨 | C42: 남아 넘치다
A44: ※ 트리거는 재화 관련 문맥을 기계적으로 골라내기 위한 장치입니다. 트리거가 있다고 은유인 것도, 없다고 은유가 아닌 것도 아닙니다. 트리거를 포함한 절과 그 앞뒤 각 1절이 판정 대상이 됩니다.

Sheet 기본 의미 사전
A1: 글자 | B1: 기본 의미 | D1: ※ 기본 의미란 더 구체적이고 신체적 경험에 가까우며 역사적으로 앞선 의미입니다. 문맥에서 쓰인 뜻이 아닙니다. 두 의미가 다르고 앞의 것을 뒤의 것과의 비교로 이해할 수 있으면 은유로 판정합니다. 주석은 사전을 대신 찾아 준 것일 뿐이며, 주석이 있다고 은유인 것도 없다고 은유가 아닌 것도 아닙니다. 사전에 없는 글자는 직접 확인하십시오.
A2: 一 | B2: 하나
A3: 七 | B3: 일곱
A4: 三 | B4: 셋
A5: 上 | B5: 위쪽
A6: 下 | B6: 아래쪽
A7: 不 | B7: 아니다
A8: 世 | B8: 세상
A9: 中 | B9: 가운데
A10: 主 | B10: 주인
A11: 乃 | B11: 이에
A12: 久 | B12: 오래되다
A13: 之 | B13: 가다 (조사로도 쓰임)
... A470: 鼎 | B470: 솥
